{"task_id": 85, "prediction_id": 0, "generation": "def defer_fail(_failure):\n    \"\"\"Same as twisted.internet.defer.fail but delay calling errback until\n    next reactor loop\n\n    It delays by 100ms so reactor has a chance to go through readers and writers\n    before attending pending delayed calls, so do not set delay to zero.\n    \"\"\"\n    if is_asyncio_reactor_installed():\n        return defer.Deferred.fromCallable(_failure.errback, 100)\n    else:\n        return _failure\n", "message": "failed: Traceback (most recent call last):\n  File \"/codegendata/human-eval/human_eval/execution.py\", line 57, in unsafe_execute\n    exec(check_program, exec_globals)\n  File \"<string>\", line 196, in <module>\n  File \"<string>\", line 195, in test_1\nAssertionError\n", "passed": false}
{"task_id": 85, "prediction_id": 1, "generation": "def defer_fail(_failure):\n    \"\"\"Same as twisted.internet.defer.fail but delay calling errback until\n    next reactor loop\n\n    It delays by 100ms so reactor has a chance to go through readers and writers\n    before attending pending delayed calls, so do not set delay to zero.\n    \"\"\"\n    deferred = task.deferLater(\n        _failure.reactor,\n        100,\n        _failure.errback,\n        _failure.value\n    )\n    return deferred\n", "message": "failed: Traceback (most recent call last):\n  File \"/codegendata/human-eval/human_eval/execution.py\", line 57, in unsafe_execute\n    exec(check_program, exec_globals)\n  File \"<string>\", line 199, in <module>\n  File \"<string>\", line 198, in test_1\n  File \"<string>\", line 44, in defer_fail\nAttributeError: 'Failure' object has no attribute 'reactor'\n", "passed": false}
{"task_id": 85, "prediction_id": 2, "generation": "def defer_fail(_failure):\n    \"\"\"Same as twisted.internet.defer.fail but delay calling errback until\n    next reactor loop\n\n    It delays by 100ms so reactor has a chance to go through readers and writers\n    before attending pending delayed calls, so do not set delay to zero.\n    \"\"\"\n    if is_asyncio_reactor_installed():\n        return defer.Deferred.fromCallable(_failure.errback, 100)\n    else:\n        return _failure\n", "message": "failed: Traceback (most recent call last):\n  File \"/codegendata/human-eval/human_eval/execution.py\", line 57, in unsafe_execute\n    exec(check_program, exec_globals)\n  File \"<string>\", line 196, in <module>\n  File \"<string>\", line 195, in test_1\nAssertionError\n", "passed": false}
{"task_id": 85, "prediction_id": 3, "generation": "def defer_fail(_failure):\n    \"\"\"Same as twisted.internet.defer.fail but delay calling errback until\n    next reactor loop\n\n    It delays by 100ms so reactor has a chance to go through readers and writers\n    before attending pending delayed calls, so do not set delay to zero.\n    \"\"\"\n    return task.deferLater(\n        task.currentThread(), 0.1, _failure.errback)\n", "message": "failed: Traceback (most recent call last):\n  File \"/codegendata/human-eval/human_eval/execution.py\", line 57, in unsafe_execute\n    exec(check_program, exec_globals)\n  File \"<string>\", line 194, in <module>\n  File \"<string>\", line 193, in test_1\n  File \"<string>\", line 44, in defer_fail\nAttributeError: module 'twisted.internet.task' has no attribute 'currentThread'\n", "passed": false}
{"task_id": 85, "prediction_id": 4, "generation": "def defer_fail(_failure):\n    \"\"\"Same as twisted.internet.defer.fail but delay calling errback until\n    next reactor loop\n\n    It delays by 100ms so reactor has a chance to go through readers and writers\n    before attending pending delayed calls, so do not set delay to zero.\n    \"\"\"\n    return defer.Deferred(failure.Failure(_failure),\n                          callback=lambda _: None,\n                          errback=lambda _: None,\n                          chain=False)\n", "message": "failed: Traceback (most recent call last):\n  File \"/codegendata/human-eval/human_eval/execution.py\", line 57, in unsafe_execute\n    exec(check_program, exec_globals)\n  File \"<string>\", line 196, in <module>\n  File \"<string>\", line 195, in test_1\n  File \"<string>\", line 43, in defer_fail\nTypeError: Deferred.__init__() got an unexpected keyword argument 'callback'\n", "passed": false}
{"task_id": 85, "prediction_id": 5, "generation": "def defer_fail(_failure):\n    \"\"\"Same as twisted.internet.defer.fail but delay calling errback until\n    next reactor loop\n\n    It delays by 100ms so reactor has a chance to go through readers and writers\n    before attending pending delayed calls, so do not set delay to zero.\n    \"\"\"\n    if is_asyncio_reactor_installed():\n        return defer.Deferred.fromCallable(_failure.errback, 100)\n    else:\n        return _failure\n", "message": "failed: Traceback (most recent call last):\n  File \"/codegendata/human-eval/human_eval/execution.py\", line 57, in unsafe_execute\n    exec(check_program, exec_globals)\n  File \"<string>\", line 196, in <module>\n  File \"<string>\", line 195, in test_1\nAssertionError\n", "passed": false}
{"task_id": 85, "prediction_id": 6, "generation": "def defer_fail(_failure):\n    \"\"\"Same as twisted.internet.defer.fail but delay calling errback until\n    next reactor loop\n\n    It delays by 100ms so reactor has a chance to go through readers and writers\n    before attending pending delayed calls, so do not set delay to zero.\n    \"\"\"\n    return defer.Deferred(lambda: _failure.errback())\n", "message": "passed", "passed": true}
{"task_id": 85, "prediction_id": 7, "generation": "def defer_fail(_failure):\n    \"\"\"Same as twisted.internet.defer.fail but delay calling errback until\n    next reactor loop\n\n    It delays by 100ms so reactor has a chance to go through readers and writers\n    before attending pending delayed calls, so do not set delay to zero.\n    \"\"\"\n    if is_asyncio_reactor_installed():\n        return defer.Deferred.fromCallable(_failure.errback, 100)\n    else:\n        return _failure\n", "message": "failed: Traceback (most recent call last):\n  File \"/codegendata/human-eval/human_eval/execution.py\", line 57, in unsafe_execute\n    exec(check_program, exec_globals)\n  File \"<string>\", line 196, in <module>\n  File \"<string>\", line 195, in test_1\nAssertionError\n", "passed": false}
{"task_id": 85, "prediction_id": 8, "generation": "def defer_fail(_failure):\n    \"\"\"Same as twisted.internet.defer.fail but delay calling errback until\n    next reactor loop\n\n    It delays by 100ms so reactor has a chance to go through readers and writers\n    before attending pending delayed calls, so do not set delay to zero.\n    \"\"\"\n    if is_asyncio_reactor_installed():\n        return defer.Deferred.fromCallable(_failure.errback, 100)\n    else:\n        return _failure\n", "message": "failed: Traceback (most recent call last):\n  File \"/codegendata/human-eval/human_eval/execution.py\", line 57, in unsafe_execute\n    exec(check_program, exec_globals)\n  File \"<string>\", line 196, in <module>\n  File \"<string>\", line 195, in test_1\nAssertionError\n", "passed": false}
{"task_id": 85, "prediction_id": 9, "generation": "def defer_fail(_failure):\n    \"\"\"Same as twisted.internet.defer.fail but delay calling errback until\n    next reactor loop\n\n    It delays by 100ms so reactor has a chance to go through readers and writers\n    before attending pending delayed calls, so do not set delay to zero.\n    \"\"\"\n    if is_asyncio_reactor_installed():\n        return task.deferLater(task.currentThread(), 0.1, _failure.errback)\n    else:\n        return _failure\n", "message": "failed: Traceback (most recent call last):\n  File \"/codegendata/human-eval/human_eval/execution.py\", line 57, in unsafe_execute\n    exec(check_program, exec_globals)\n  File \"<string>\", line 196, in <module>\n  File \"<string>\", line 195, in test_1\nAssertionError\n", "passed": false}
{"task_id": 85, "prediction_id": 10, "generation": "def defer_fail(_failure):\n    \"\"\"Same as twisted.internet.defer.fail but delay calling errback until\n    next reactor loop\n\n    It delays by 100ms so reactor has a chance to go through readers and writers\n    before attending pending delayed calls, so do not set delay to zero.\n    \"\"\"\n    if is_asyncio_reactor_installed():\n        return defer.Deferred.fromCallable(_failure.errback, 100)\n    else:\n        return _failure.errback()\n", "message": "failed: Traceback (most recent call last):\n  File \"/codegendata/human-eval/human_eval/execution.py\", line 57, in unsafe_execute\n    exec(check_program, exec_globals)\n  File \"<string>\", line 196, in <module>\n  File \"<string>\", line 195, in test_1\n  File \"<string>\", line 46, in defer_fail\nAttributeError: 'Failure' object has no attribute 'errback'\n", "passed": false}
{"task_id": 85, "prediction_id": 11, "generation": "def defer_fail(_failure):\n    \"\"\"Same as twisted.internet.defer.fail but delay calling errback until\n    next reactor loop\n\n    It delays by 100ms so reactor has a chance to go through readers and writers\n    before attending pending delayed calls, so do not set delay to zero.\n    \"\"\"\n    return defer.Deferred() \\\n        .addErrback(_failure) \\\n        .addCallback(lambda _: defer.Deferred()) \\\n        .addCallback(lambda _: _failure)\n", "message": "failed: Traceback (most recent call last):\n  File \"/codegendata/human-eval/human_eval/execution.py\", line 57, in unsafe_execute\n    exec(check_program, exec_globals)\n  File \"<string>\", line 196, in <module>\n  File \"<string>\", line 195, in test_1\n  File \"<string>\", line 44, in defer_fail\n  File \"/usr/local/lib/python3.10/site-packages/twisted/internet/defer.py\", line 656, in addErrback\n    return self.addCallbacks(\n  File \"/usr/local/lib/python3.10/site-packages/twisted/internet/defer.py\", line 523, in addCallbacks\n    assert callable(errback)\nAssertionError\n", "passed": false}
{"task_id": 85, "prediction_id": 12, "generation": "def defer_fail(_failure):\n    \"\"\"Same as twisted.internet.defer.fail but delay calling errback until\n    next reactor loop\n\n    It delays by 100ms so reactor has a chance to go through readers and writers\n    before attending pending delayed calls, so do not set delay to zero.\n    \"\"\"\n    if is_asyncio_reactor_installed():\n        return defer.Deferred.fromCallable(_failure.errback, 100)\n    else:\n        return _failure\n", "message": "failed: Traceback (most recent call last):\n  File \"/codegendata/human-eval/human_eval/execution.py\", line 57, in unsafe_execute\n    exec(check_program, exec_globals)\n  File \"<string>\", line 196, in <module>\n  File \"<string>\", line 195, in test_1\nAssertionError\n", "passed": false}
{"task_id": 85, "prediction_id": 13, "generation": "def defer_fail(_failure):\n    \"\"\"Same as twisted.internet.defer.fail but delay calling errback until\n    next reactor loop\n\n    It delays by 100ms so reactor has a chance to go through readers and writers\n    before attending pending delayed calls, so do not set delay to zero.\n    \"\"\"\n    defer.fail(_failure).addErrback(lambda f: defer.fail(_failure).addErrback(lambda f: f.errback()))\n    return defer.Deferred()\n", "message": "passed", "passed": true}
{"task_id": 85, "prediction_id": 14, "generation": "def defer_fail(_failure):\n    \"\"\"Same as twisted.internet.defer.fail but delay calling errback until\n    next reactor loop\n\n    It delays by 100ms so reactor has a chance to go through readers and writers\n    before attending pending delayed calls, so do not set delay to zero.\n    \"\"\"\n    if is_asyncio_reactor_installed():\n        return defer.Deferred.fromCallable(_failure.errback, 100)\n    else:\n        return _failure.errback()\n", "message": "failed: Traceback (most recent call last):\n  File \"/codegendata/human-eval/human_eval/execution.py\", line 57, in unsafe_execute\n    exec(check_program, exec_globals)\n  File \"<string>\", line 196, in <module>\n  File \"<string>\", line 195, in test_1\n  File \"<string>\", line 46, in defer_fail\nAttributeError: 'Failure' object has no attribute 'errback'\n", "passed": false}
{"task_id": 85, "prediction_id": 15, "generation": "def defer_fail(_failure):\n    \"\"\"Same as twisted.internet.defer.fail but delay calling errback until\n    next reactor loop\n\n    It delays by 100ms so reactor has a chance to go through readers and writers\n    before attending pending delayed calls, so do not set delay to zero.\n    \"\"\"\n    if is_asyncio_reactor_installed():\n        return defer.Deferred.fromCallable(_failure.errback, 100)\n    else:\n        return _failure\n", "message": "failed: Traceback (most recent call last):\n  File \"/codegendata/human-eval/human_eval/execution.py\", line 57, in unsafe_execute\n    exec(check_program, exec_globals)\n  File \"<string>\", line 196, in <module>\n  File \"<string>\", line 195, in test_1\nAssertionError\n", "passed": false}
{"task_id": 85, "prediction_id": 16, "generation": "def defer_fail(_failure):\n    \"\"\"Same as twisted.internet.defer.fail but delay calling errback until\n    next reactor loop\n\n    It delays by 100ms so reactor has a chance to go through readers and writers\n    before attending pending delayed calls, so do not set delay to zero.\n    \"\"\"\n    if is_asyncio_reactor_installed():\n        return task.deferLater(\n            _failure.reactor,\n            100,\n            _failure.errback,\n            _failure.value,\n        )\n    else:\n        return _failure.errback()\n", "message": "failed: Traceback (most recent call last):\n  File \"/codegendata/human-eval/human_eval/execution.py\", line 57, in unsafe_execute\n    exec(check_program, exec_globals)\n  File \"<string>\", line 201, in <module>\n  File \"<string>\", line 200, in test_1\n  File \"<string>\", line 51, in defer_fail\nAttributeError: 'Failure' object has no attribute 'errback'\n", "passed": false}
{"task_id": 85, "prediction_id": 17, "generation": "def defer_fail(_failure):\n    \"\"\"Same as twisted.internet.defer.fail but delay calling errback until\n    next reactor loop\n\n    It delays by 100ms so reactor has a chance to go through readers and writers\n    before attending pending delayed calls, so do not set delay to zero.\n    \"\"\"\n    if is_asyncio_reactor_installed():\n        return defer.Deferred.fromCallable(_failure.errback, 100)\n    else:\n        return _failure\n", "message": "failed: Traceback (most recent call last):\n  File \"/codegendata/human-eval/human_eval/execution.py\", line 57, in unsafe_execute\n    exec(check_program, exec_globals)\n  File \"<string>\", line 196, in <module>\n  File \"<string>\", line 195, in test_1\nAssertionError\n", "passed": false}
{"task_id": 85, "prediction_id": 18, "generation": "def defer_fail(_failure):\n    \"\"\"Same as twisted.internet.defer.fail but delay calling errback until\n    next reactor loop\n\n    It delays by 100ms so reactor has a chance to go through readers and writers\n    before attending pending delayed calls, so do not set delay to zero.\n    \"\"\"\n    if is_asyncio_reactor_installed():\n        return defer.Deferred.fromCallable(_failure.errback, 100)\n    else:\n        return _failure\n", "message": "failed: Traceback (most recent call last):\n  File \"/codegendata/human-eval/human_eval/execution.py\", line 57, in unsafe_execute\n    exec(check_program, exec_globals)\n  File \"<string>\", line 196, in <module>\n  File \"<string>\", line 195, in test_1\nAssertionError\n", "passed": false}
{"task_id": 85, "prediction_id": 19, "generation": "def defer_fail(_failure):\n    \"\"\"Same as twisted.internet.defer.fail but delay calling errback until\n    next reactor loop\n\n    It delays by 100ms so reactor has a chance to go through readers and writers\n    before attending pending delayed calls, so do not set delay to zero.\n    \"\"\"\n    return task.deferLater(\n        _failure.reactor,\n        100,\n        _failure.errback,\n        _failure.value\n    )\n", "message": "failed: Traceback (most recent call last):\n  File \"/codegendata/human-eval/human_eval/execution.py\", line 57, in unsafe_execute\n    exec(check_program, exec_globals)\n  File \"<string>\", line 198, in <module>\n  File \"<string>\", line 197, in test_1\n  File \"<string>\", line 44, in defer_fail\nAttributeError: 'Failure' object has no attribute 'reactor'\n", "passed": false}
{"task_id": 85, "prediction_id": 20, "generation": "def defer_fail(_failure):\n    \"\"\"Same as twisted.internet.defer.fail but delay calling errback until\n    next reactor loop\n\n    It delays by 100ms so reactor has a chance to go through readers and writers\n    before attending pending delayed calls, so do not set delay to zero.\n    \"\"\"\n    if is_asyncio_reactor_installed():\n        return defer.Deferred.fromCallable(_failure.errback, 100)\n    else:\n        return _failure\n", "message": "failed: Traceback (most recent call last):\n  File \"/codegendata/human-eval/human_eval/execution.py\", line 57, in unsafe_execute\n    exec(check_program, exec_globals)\n  File \"<string>\", line 196, in <module>\n  File \"<string>\", line 195, in test_1\nAssertionError\n", "passed": false}
{"task_id": 85, "prediction_id": 21, "generation": "def defer_fail(_failure):\n    \"\"\"Same as twisted.internet.defer.fail but delay calling errback until\n    next reactor loop\n\n    It delays by 100ms so reactor has a chance to go through readers and writers\n    before attending pending delayed calls, so do not set delay to zero.\n    \"\"\"\n    deferred = task.deferLater(\n        _failure.reactor,\n        100,\n        _failure.errback\n    )\n    deferred.addErrback(_failure.errback)\n    return deferred\n", "message": "failed: Traceback (most recent call last):\n  File \"/codegendata/human-eval/human_eval/execution.py\", line 57, in unsafe_execute\n    exec(check_program, exec_globals)\n  File \"<string>\", line 199, in <module>\n  File \"<string>\", line 198, in test_1\n  File \"<string>\", line 44, in defer_fail\nAttributeError: 'Failure' object has no attribute 'reactor'\n", "passed": false}
{"task_id": 85, "prediction_id": 22, "generation": "def defer_fail(_failure):\n    \"\"\"Same as twisted.internet.defer.fail but delay calling errback until\n    next reactor loop\n\n    It delays by 100ms so reactor has a chance to go through readers and writers\n    before attending pending delayed calls, so do not set delay to zero.\n    \"\"\"\n    if is_asyncio_reactor_installed():\n        return defer.Deferred.fromCallable(_failure.errback).addErrback(\n            lambda _: _failure.errback()\n        )\n    else:\n        return _failure.errback()\n", "message": "failed: Traceback (most recent call last):\n  File \"/codegendata/human-eval/human_eval/execution.py\", line 57, in unsafe_execute\n    exec(check_program, exec_globals)\n  File \"<string>\", line 198, in <module>\n  File \"<string>\", line 197, in test_1\n  File \"<string>\", line 48, in defer_fail\nAttributeError: 'Failure' object has no attribute 'errback'\n", "passed": false}
{"task_id": 85, "prediction_id": 23, "generation": "def defer_fail(_failure):\n    \"\"\"Same as twisted.internet.defer.fail but delay calling errback until\n    next reactor loop\n\n    It delays by 100ms so reactor has a chance to go through readers and writers\n    before attending pending delayed calls, so do not set delay to zero.\n    \"\"\"\n    return defer.Deferred() \\\n        .addErrback(_failure) \\\n        .addCallback(lambda _: _failure.errback()) \\\n        .addCallback(lambda _: _failure.errback()) \\\n        .addErrback(lambda _: _failure.errback()) \\\n        .addCallback(lambda _: _failure.errback()) \\\n        .addCallback(lambda _: _failure.errback()) \\\n        .addCallback(lambda _: _failure.errback()) \\\n        .addCallback(lambda _: _failure.errback()) \\\n        .addCallback(lambda _: _failure.errback()) \\\n        .addCallback(lambda _: _failure.errback()) \\\n        .addCallback(lambda _: _failure.errback()) \\\n        .addCallback(lambda _: _failure.errback()) \\\n        .addCallback(lambda _: _failure.errback()) \\\n        .addCallback(lambda _: _failure.errback()) \\\n        .addCallback(lambda _: _failure.errback()) \\\n        .addCallback(lambda _: _failure.errback()) \\\n        .addCallback(lambda _: _failure.errback()) \\\n        .addCallback(lambda _: _failure.errback()) \\\n        .addCallback(lambda _: _failure.errback()) \\\n        .addCallback(lambda _: _failure.errback()) \\\n        .addCallback(lambda _: _failure.errback()) \\\n        .addCallback(lambda _: _failure.errback()) \\\n        .addCallback(lambda _: _failure.errback()) \\\n        .addCallback(lambda _: _failure.errback()) \\\n        .addCallback(lambda _: _failure.errback()) \\\n        .addCallback(lambda _: _failure.errback()) \\\n        .addCallback(lambda _: _failure.errback()) \\\n        .addCallback(lambda _: _failure.errback()) \\\n        .addCallback(lambda _: _failure.errback()) \\\n        .addCallback(lambda _: _failure.", "message": "failed: Traceback (most recent call last):\n  File \"/codegendata/human-eval/human_eval/execution.py\", line 57, in unsafe_execute\n    exec(check_program, exec_globals)\n  File \"<string>\", line 73\n    .addCallback(lambda _: _failure.\n                ^\nSyntaxError: '(' was never closed\n", "passed": false}
{"task_id": 85, "prediction_id": 24, "generation": "def defer_fail(_failure):\n    \"\"\"Same as twisted.internet.defer.fail but delay calling errback until\n    next reactor loop\n\n    It delays by 100ms so reactor has a chance to go through readers and writers\n    before attending pending delayed calls, so do not set delay to zero.\n    \"\"\"\n    return defer.Deferred(callback=_failure.errback, errback=_failure.errback)\n", "message": "failed: Traceback (most recent call last):\n  File \"/codegendata/human-eval/human_eval/execution.py\", line 57, in unsafe_execute\n    exec(check_program, exec_globals)\n  File \"<string>\", line 193, in <module>\n  File \"<string>\", line 192, in test_1\n  File \"<string>\", line 43, in defer_fail\nAttributeError: 'Failure' object has no attribute 'errback'\n", "passed": false}
{"task_id": 85, "prediction_id": 25, "generation": "def defer_fail(_failure):\n    \"\"\"Same as twisted.internet.defer.fail but delay calling errback until\n    next reactor loop\n\n    It delays by 100ms so reactor has a chance to go through readers and writers\n    before attending pending delayed calls, so do not set delay to zero.\n    \"\"\"\n    return defer.Deferred(_failure.errback, 100)\n", "message": "failed: Traceback (most recent call last):\n  File \"/codegendata/human-eval/human_eval/execution.py\", line 57, in unsafe_execute\n    exec(check_program, exec_globals)\n  File \"<string>\", line 193, in <module>\n  File \"<string>\", line 192, in test_1\n  File \"<string>\", line 43, in defer_fail\nAttributeError: 'Failure' object has no attribute 'errback'\n", "passed": false}
{"task_id": 85, "prediction_id": 26, "generation": "def defer_fail(_failure):\n    \"\"\"Same as twisted.internet.defer.fail but delay calling errback until\n    next reactor loop\n\n    It delays by 100ms so reactor has a chance to go through readers and writers\n    before attending pending delayed calls, so do not set delay to zero.\n    \"\"\"\n    if is_asyncio_reactor_installed():\n        return defer.Deferred.fromCallable(_failure.errback, 100)\n    else:\n        return _failure\n", "message": "failed: Traceback (most recent call last):\n  File \"/codegendata/human-eval/human_eval/execution.py\", line 57, in unsafe_execute\n    exec(check_program, exec_globals)\n  File \"<string>\", line 196, in <module>\n  File \"<string>\", line 195, in test_1\nAssertionError\n", "passed": false}
{"task_id": 85, "prediction_id": 27, "generation": "def defer_fail(_failure):\n    \"\"\"Same as twisted.internet.defer.fail but delay calling errback until\n    next reactor loop\n\n    It delays by 100ms so reactor has a chance to go through readers and writers\n    before attending pending delayed calls, so do not set delay to zero.\n    \"\"\"\n    if is_asyncio_reactor_installed():\n        return defer.Deferred.fromCallable(_failure.errback, 100)\n    else:\n        return _failure\n\n", "message": "failed: Traceback (most recent call last):\n  File \"/codegendata/human-eval/human_eval/execution.py\", line 57, in unsafe_execute\n    exec(check_program, exec_globals)\n  File \"<string>\", line 197, in <module>\n  File \"<string>\", line 196, in test_1\nAssertionError\n", "passed": false}
{"task_id": 85, "prediction_id": 28, "generation": "def defer_fail(_failure):\n    \"\"\"Same as twisted.internet.defer.fail but delay calling errback until\n    next reactor loop\n\n    It delays by 100ms so reactor has a chance to go through readers and writers\n    before attending pending delayed calls, so do not set delay to zero.\n    \"\"\"\n    if is_asyncio_reactor_installed():\n        return defer.Deferred.fromCallable(_failure.errback, 100)\n    else:\n        return _failure\n", "message": "failed: Traceback (most recent call last):\n  File \"/codegendata/human-eval/human_eval/execution.py\", line 57, in unsafe_execute\n    exec(check_program, exec_globals)\n  File \"<string>\", line 196, in <module>\n  File \"<string>\", line 195, in test_1\nAssertionError\n", "passed": false}
{"task_id": 85, "prediction_id": 29, "generation": "def defer_fail(_failure):\n    \"\"\"Same as twisted.internet.defer.fail but delay calling errback until\n    next reactor loop\n\n    It delays by 100ms so reactor has a chance to go through readers and writers\n    before attending pending delayed calls, so do not set delay to zero.\n    \"\"\"\n    def _inner(self):\n        self.errback(_failure)\n        self.addErrback(defer.Deferred.errback, _failure)\n        self.addBoth(defer.Deferred.errback, _failure)\n        return self\n    return _inner\n", "message": "failed: Traceback (most recent call last):\n  File \"/codegendata/human-eval/human_eval/execution.py\", line 57, in unsafe_execute\n    exec(check_program, exec_globals)\n  File \"<string>\", line 198, in <module>\n  File \"<string>\", line 197, in test_1\nAssertionError\n", "passed": false}
{"task_id": 85, "prediction_id": 30, "generation": "def defer_fail(_failure):\n    \"\"\"Same as twisted.internet.defer.fail but delay calling errback until\n    next reactor loop\n\n    It delays by 100ms so reactor has a chance to go through readers and writers\n    before attending pending delayed calls, so do not set delay to zero.\n    \"\"\"\n    deferred = task.deferLater(\n        _failure.reactor,\n        100,\n        _failure.errback\n    )\n    return deferred\n", "message": "failed: Traceback (most recent call last):\n  File \"/codegendata/human-eval/human_eval/execution.py\", line 57, in unsafe_execute\n    exec(check_program, exec_globals)\n  File \"<string>\", line 198, in <module>\n  File \"<string>\", line 197, in test_1\n  File \"<string>\", line 44, in defer_fail\nAttributeError: 'Failure' object has no attribute 'reactor'\n", "passed": false}
{"task_id": 85, "prediction_id": 31, "generation": "def defer_fail(_failure):\n    \"\"\"Same as twisted.internet.defer.fail but delay calling errback until\n    next reactor loop\n\n    It delays by 100ms so reactor has a chance to go through readers and writers\n    before attending pending delayed calls, so do not set delay to zero.\n    \"\"\"\n    return task.deferLater(\n        task.currentThread(), 0.1, _failure.errback)\n", "message": "failed: Traceback (most recent call last):\n  File \"/codegendata/human-eval/human_eval/execution.py\", line 57, in unsafe_execute\n    exec(check_program, exec_globals)\n  File \"<string>\", line 194, in <module>\n  File \"<string>\", line 193, in test_1\n  File \"<string>\", line 44, in defer_fail\nAttributeError: module 'twisted.internet.task' has no attribute 'currentThread'\n", "passed": false}
{"task_id": 85, "prediction_id": 32, "generation": "def defer_fail(_failure):\n    \"\"\"Same as twisted.internet.defer.fail but delay calling errback until\n    next reactor loop\n\n    It delays by 100ms so reactor has a chance to go through readers and writers\n    before attending pending delayed calls, so do not set delay to zero.\n    \"\"\"\n    if is_asyncio_reactor_installed():\n        return defer.Deferred.fromCallable(_failure.errback)\n    else:\n        return _failure.errback()\n", "message": "failed: Traceback (most recent call last):\n  File \"/codegendata/human-eval/human_eval/execution.py\", line 57, in unsafe_execute\n    exec(check_program, exec_globals)\n  File \"<string>\", line 196, in <module>\n  File \"<string>\", line 195, in test_1\n  File \"<string>\", line 46, in defer_fail\nAttributeError: 'Failure' object has no attribute 'errback'\n", "passed": false}
{"task_id": 85, "prediction_id": 33, "generation": "def defer_fail(_failure):\n    \"\"\"Same as twisted.internet.defer.fail but delay calling errback until\n    next reactor loop\n\n    It delays by 100ms so reactor has a chance to go through readers and writers\n    before attending pending delayed calls, so do not set delay to zero.\n    \"\"\"\n    return defer.Deferred(lambda: _failure.errback())\n", "message": "passed", "passed": true}
{"task_id": 85, "prediction_id": 34, "generation": "def defer_fail(_failure):\n    \"\"\"Same as twisted.internet.defer.fail but delay calling errback until\n    next reactor loop\n\n    It delays by 100ms so reactor has a chance to go through readers and writers\n    before attending pending delayed calls, so do not set delay to zero.\n    \"\"\"\n    def _inner(f):\n        @wraps(f)\n        def _inner_wrapper(*args, **kwargs):\n            return defer.Deferred(\n                callback=f,\n                errback=lambda f: _failure(f),\n                chain=True,\n            ).addErrback(lambda f: _failure(f))\n        return _inner_wrapper\n    return _inner\n", "message": "failed: Traceback (most recent call last):\n  File \"/codegendata/human-eval/human_eval/execution.py\", line 57, in unsafe_execute\n    exec(check_program, exec_globals)\n  File \"<string>\", line 202, in <module>\n  File \"<string>\", line 201, in test_1\nAssertionError\n", "passed": false}
{"task_id": 85, "prediction_id": 35, "generation": "def defer_fail(_failure):\n    \"\"\"Same as twisted.internet.defer.fail but delay calling errback until\n    next reactor loop\n\n    It delays by 100ms so reactor has a chance to go through readers and writers\n    before attending pending delayed calls, so do not set delay to zero.\n    \"\"\"\n    if is_asyncio_reactor_installed():\n        return defer.Deferred.fromCallable(_failure.errback, 100)\n    else:\n        return _failure\n", "message": "failed: Traceback (most recent call last):\n  File \"/codegendata/human-eval/human_eval/execution.py\", line 57, in unsafe_execute\n    exec(check_program, exec_globals)\n  File \"<string>\", line 196, in <module>\n  File \"<string>\", line 195, in test_1\nAssertionError\n", "passed": false}
{"task_id": 85, "prediction_id": 36, "generation": "def defer_fail(_failure):\n    \"\"\"Same as twisted.internet.defer.fail but delay calling errback until\n    next reactor loop\n\n    It delays by 100ms so reactor has a chance to go through readers and writers\n    before attending pending delayed calls, so do not set delay to zero.\n    \"\"\"\n    if is_asyncio_reactor_installed():\n        return defer.Deferred.fromCallable(_failure.errback)\n    else:\n        return defer.Deferred.fromCallable(_failure.errback, 100)\n", "message": "failed: Traceback (most recent call last):\n  File \"/codegendata/human-eval/human_eval/execution.py\", line 57, in unsafe_execute\n    exec(check_program, exec_globals)\n  File \"<string>\", line 196, in <module>\n  File \"<string>\", line 195, in test_1\n  File \"<string>\", line 46, in defer_fail\nAttributeError: type object 'Deferred' has no attribute 'fromCallable'\n", "passed": false}
{"task_id": 85, "prediction_id": 37, "generation": "def defer_fail(_failure):\n    \"\"\"Same as twisted.internet.defer.fail but delay calling errback until\n    next reactor loop\n\n    It delays by 100ms so reactor has a chance to go through readers and writers\n    before attending pending delayed calls, so do not set delay to zero.\n    \"\"\"\n    if is_asyncio_reactor_installed():\n        return defer.Deferred.fromCallable(_failure.errback, 100)\n    else:\n        return _failure.errback()\n", "message": "failed: Traceback (most recent call last):\n  File \"/codegendata/human-eval/human_eval/execution.py\", line 57, in unsafe_execute\n    exec(check_program, exec_globals)\n  File \"<string>\", line 196, in <module>\n  File \"<string>\", line 195, in test_1\n  File \"<string>\", line 46, in defer_fail\nAttributeError: 'Failure' object has no attribute 'errback'\n", "passed": false}
{"task_id": 85, "prediction_id": 38, "generation": "def defer_fail(_failure):\n    \"\"\"Same as twisted.internet.defer.fail but delay calling errback until\n    next reactor loop\n\n    It delays by 100ms so reactor has a chance to go through readers and writers\n    before attending pending delayed calls, so do not set delay to zero.\n    \"\"\"\n    if is_asyncio_reactor_installed():\n        return defer.Deferred.fromCallable(lambda: _failure.errback())\n    else:\n        return defer.Deferred.fromCallable(lambda: _failure.errback(),\n                                           delay=0.1)\n", "message": "failed: Traceback (most recent call last):\n  File \"/codegendata/human-eval/human_eval/execution.py\", line 57, in unsafe_execute\n    exec(check_program, exec_globals)\n  File \"<string>\", line 197, in <module>\n  File \"<string>\", line 196, in test_1\n  File \"<string>\", line 46, in defer_fail\nAttributeError: type object 'Deferred' has no attribute 'fromCallable'\n", "passed": false}
{"task_id": 85, "prediction_id": 39, "generation": "def defer_fail(_failure):\n    \"\"\"Same as twisted.internet.defer.fail but delay calling errback until\n    next reactor loop\n\n    It delays by 100ms so reactor has a chance to go through readers and writers\n    before attending pending delayed calls, so do not set delay to zero.\n    \"\"\"\n    return task.deferLater(\n        _failure.reactor,\n        100,\n        _failure.errback,\n        _failure.value\n    )\n", "message": "failed: Traceback (most recent call last):\n  File \"/codegendata/human-eval/human_eval/execution.py\", line 57, in unsafe_execute\n    exec(check_program, exec_globals)\n  File \"<string>\", line 198, in <module>\n  File \"<string>\", line 197, in test_1\n  File \"<string>\", line 44, in defer_fail\nAttributeError: 'Failure' object has no attribute 'reactor'\n", "passed": false}
{"task_id": 85, "prediction_id": 40, "generation": "def defer_fail(_failure):\n    \"\"\"Same as twisted.internet.defer.fail but delay calling errback until\n    next reactor loop\n\n    It delays by 100ms so reactor has a chance to go through readers and writers\n    before attending pending delayed calls, so do not set delay to zero.\n    \"\"\"\n    def _inner(self):\n        self.errback(_failure)\n        self.addErrback(_inner)\n    return _inner\n", "message": "failed: Traceback (most recent call last):\n  File \"/codegendata/human-eval/human_eval/execution.py\", line 57, in unsafe_execute\n    exec(check_program, exec_globals)\n  File \"<string>\", line 196, in <module>\n  File \"<string>\", line 195, in test_1\nAssertionError\n", "passed": false}
{"task_id": 85, "prediction_id": 41, "generation": "def defer_fail(_failure):\n    \"\"\"Same as twisted.internet.defer.fail but delay calling errback until\n    next reactor loop\n\n    It delays by 100ms so reactor has a chance to go through readers and writers\n    before attending pending delayed calls, so do not set delay to zero.\n    \"\"\"\n    if not is_asyncio_reactor_installed():\n        return _failure\n    return defer.Deferred.fromCallable(\n        lambda: _failure.errback(),\n        100,\n    )\n", "message": "failed: Traceback (most recent call last):\n  File \"/codegendata/human-eval/human_eval/execution.py\", line 57, in unsafe_execute\n    exec(check_program, exec_globals)\n  File \"<string>\", line 198, in <module>\n  File \"<string>\", line 197, in test_1\nAssertionError\n", "passed": false}
{"task_id": 85, "prediction_id": 42, "generation": "def defer_fail(_failure):\n    \"\"\"Same as twisted.internet.defer.fail but delay calling errback until\n    next reactor loop\n\n    It delays by 100ms so reactor has a chance to go through readers and writers\n    before attending pending delayed calls, so do not set delay to zero.\n    \"\"\"\n    if is_asyncio_reactor_installed():\n        return defer.Deferred.fromCallable(\n            lambda: _failure.errback(),\n            100,\n        )\n    else:\n        return _failure\n\n", "message": "failed: Traceback (most recent call last):\n  File \"/codegendata/human-eval/human_eval/execution.py\", line 57, in unsafe_execute\n    exec(check_program, exec_globals)\n  File \"<string>\", line 200, in <module>\n  File \"<string>\", line 199, in test_1\nAssertionError\n", "passed": false}
{"task_id": 85, "prediction_id": 43, "generation": "def defer_fail(_failure):\n    \"\"\"Same as twisted.internet.defer.fail but delay calling errback until\n    next reactor loop\n\n    It delays by 100ms so reactor has a chance to go through readers and writers\n    before attending pending delayed calls, so do not set delay to zero.\n    \"\"\"\n    if is_asyncio_reactor_installed():\n        return defer.Deferred.fromCallable(_failure.errback)\n    else:\n        return _failure.errback()\n", "message": "failed: Traceback (most recent call last):\n  File \"/codegendata/human-eval/human_eval/execution.py\", line 57, in unsafe_execute\n    exec(check_program, exec_globals)\n  File \"<string>\", line 196, in <module>\n  File \"<string>\", line 195, in test_1\n  File \"<string>\", line 46, in defer_fail\nAttributeError: 'Failure' object has no attribute 'errback'\n", "passed": false}
{"task_id": 85, "prediction_id": 44, "generation": "def defer_fail(_failure):\n    \"\"\"Same as twisted.internet.defer.fail but delay calling errback until\n    next reactor loop\n\n    It delays by 100ms so reactor has a chance to go through readers and writers\n    before attending pending delayed calls, so do not set delay to zero.\n    \"\"\"\n    if is_asyncio_reactor_installed():\n        return defer.Deferred.fromCallable(_failure.errback)\n    else:\n        return defer.Deferred.fromCallable(_failure.errback, delay=0.1)\n", "message": "failed: Traceback (most recent call last):\n  File \"/codegendata/human-eval/human_eval/execution.py\", line 57, in unsafe_execute\n    exec(check_program, exec_globals)\n  File \"<string>\", line 196, in <module>\n  File \"<string>\", line 195, in test_1\n  File \"<string>\", line 46, in defer_fail\nAttributeError: type object 'Deferred' has no attribute 'fromCallable'\n", "passed": false}
{"task_id": 85, "prediction_id": 45, "generation": "def defer_fail(_failure):\n    \"\"\"Same as twisted.internet.defer.fail but delay calling errback until\n    next reactor loop\n\n    It delays by 100ms so reactor has a chance to go through readers and writers\n    before attending pending delayed calls, so do not set delay to zero.\n    \"\"\"\n    if is_asyncio_reactor_installed():\n        return defer.Deferred.fromCallable(\n            lambda: _failure.errback(),\n            100,\n            _failure.errback\n        )\n    else:\n        return _failure\n", "message": "failed: Traceback (most recent call last):\n  File \"/codegendata/human-eval/human_eval/execution.py\", line 57, in unsafe_execute\n    exec(check_program, exec_globals)\n  File \"<string>\", line 200, in <module>\n  File \"<string>\", line 199, in test_1\nAssertionError\n", "passed": false}
{"task_id": 85, "prediction_id": 46, "generation": "def defer_fail(_failure):\n    \"\"\"Same as twisted.internet.defer.fail but delay calling errback until\n    next reactor loop\n\n    It delays by 100ms so reactor has a chance to go through readers and writers\n    before attending pending delayed calls, so do not set delay to zero.\n    \"\"\"\n    if is_asyncio_reactor_installed():\n        return defer.Deferred.fromCallable(_failure.errback)\n    else:\n        return _failure.errback()\n", "message": "failed: Traceback (most recent call last):\n  File \"/codegendata/human-eval/human_eval/execution.py\", line 57, in unsafe_execute\n    exec(check_program, exec_globals)\n  File \"<string>\", line 196, in <module>\n  File \"<string>\", line 195, in test_1\n  File \"<string>\", line 46, in defer_fail\nAttributeError: 'Failure' object has no attribute 'errback'\n", "passed": false}
{"task_id": 85, "prediction_id": 47, "generation": "def defer_fail(_failure):\n    \"\"\"Same as twisted.internet.defer.fail but delay calling errback until\n    next reactor loop\n\n    It delays by 100ms so reactor has a chance to go through readers and writers\n    before attending pending delayed calls, so do not set delay to zero.\n    \"\"\"\n    if is_asyncio_reactor_installed():\n        return defer.Deferred.fromCallable(_failure.errback, 100)\n    else:\n        return _failure\n\n", "message": "failed: Traceback (most recent call last):\n  File \"/codegendata/human-eval/human_eval/execution.py\", line 57, in unsafe_execute\n    exec(check_program, exec_globals)\n  File \"<string>\", line 197, in <module>\n  File \"<string>\", line 196, in test_1\nAssertionError\n", "passed": false}
{"task_id": 85, "prediction_id": 48, "generation": "def defer_fail(_failure):\n    \"\"\"Same as twisted.internet.defer.fail but delay calling errback until\n    next reactor loop\n\n    It delays by 100ms so reactor has a chance to go through readers and writers\n    before attending pending delayed calls, so do not set delay to zero.\n    \"\"\"\n    def _inner(f):\n        @wraps(f)\n        def _inner_wrapper(*args, **kwargs):\n            return defer.Deferred(_failure, errback=f, args=args, kwargs=kwargs)\n        return _inner_wrapper\n    return _inner\n", "message": "failed: Traceback (most recent call last):\n  File \"/codegendata/human-eval/human_eval/execution.py\", line 57, in unsafe_execute\n    exec(check_program, exec_globals)\n  File \"<string>\", line 198, in <module>\n  File \"<string>\", line 197, in test_1\nAssertionError\n", "passed": false}
{"task_id": 85, "prediction_id": 49, "generation": "def defer_fail(_failure):\n    \"\"\"Same as twisted.internet.defer.fail but delay calling errback until\n    next reactor loop\n\n    It delays by 100ms so reactor has a chance to go through readers and writers\n    before attending pending delayed calls, so do not set delay to zero.\n    \"\"\"\n    if is_asyncio_reactor_installed():\n        return defer.Deferred.fromCallable(_failure.errback, 100)\n    else:\n        return _failure\n", "message": "failed: Traceback (most recent call last):\n  File \"/codegendata/human-eval/human_eval/execution.py\", line 57, in unsafe_execute\n    exec(check_program, exec_globals)\n  File \"<string>\", line 196, in <module>\n  File \"<string>\", line 195, in test_1\nAssertionError\n", "passed": false}
