{"task_id": 102, "prediction_id": 0, "generation": "def failure_to_exc_info(failure):\n    \"\"\"Extract exc_info from Failure instances\"\"\"\n    if isinstance(failure, Failure):\n        return failure.value.exc_info()\n    return None\n", "message": "failed: Traceback (most recent call last):\n  File \"/codegendata/human-eval/human_eval/execution.py\", line 57, in unsafe_execute\n    exec(check_program, exec_globals)\n  File \"<string>\", line 249, in <module>\n  File \"<string>\", line 248, in test_0\n  File \"<string>\", line 44, in failure_to_exc_info\nAttributeError: 'ValueError' object has no attribute 'exc_info'\n", "passed": false}
{"task_id": 102, "prediction_id": 1, "generation": "def failure_to_exc_info(failure):\n    \"\"\"Extract exc_info from Failure instances\"\"\"\n    if isinstance(failure, Failure):\n        return failure.value.exc_info()\n    return None\n", "message": "failed: Traceback (most recent call last):\n  File \"/codegendata/human-eval/human_eval/execution.py\", line 57, in unsafe_execute\n    exec(check_program, exec_globals)\n  File \"<string>\", line 249, in <module>\n  File \"<string>\", line 248, in test_0\n  File \"<string>\", line 44, in failure_to_exc_info\nAttributeError: 'ValueError' object has no attribute 'exc_info'\n", "passed": false}
{"task_id": 102, "prediction_id": 2, "generation": "def failure_to_exc_info(failure):\n    \"\"\"Extract exc_info from Failure instances\"\"\"\n    if isinstance(failure, Failure):\n        return failure.value.exc_info()\n    return None\n", "message": "failed: Traceback (most recent call last):\n  File \"/codegendata/human-eval/human_eval/execution.py\", line 57, in unsafe_execute\n    exec(check_program, exec_globals)\n  File \"<string>\", line 249, in <module>\n  File \"<string>\", line 248, in test_0\n  File \"<string>\", line 44, in failure_to_exc_info\nAttributeError: 'ValueError' object has no attribute 'exc_info'\n", "passed": false}
{"task_id": 102, "prediction_id": 3, "generation": "def failure_to_exc_info(failure):\n    \"\"\"Extract exc_info from Failure instances\"\"\"\n    if isinstance(failure, Failure):\n        return failure.value.exc_info()\n    return None\n", "message": "failed: Traceback (most recent call last):\n  File \"/codegendata/human-eval/human_eval/execution.py\", line 57, in unsafe_execute\n    exec(check_program, exec_globals)\n  File \"<string>\", line 249, in <module>\n  File \"<string>\", line 248, in test_0\n  File \"<string>\", line 44, in failure_to_exc_info\nAttributeError: 'ValueError' object has no attribute 'exc_info'\n", "passed": false}
{"task_id": 102, "prediction_id": 4, "generation": "def failure_to_exc_info(failure):\n    \"\"\"Extract exc_info from Failure instances\"\"\"\n    if isinstance(failure, Failure):\n        return failure.value.exc_info()\n    else:\n        return failure\n", "message": "failed: Traceback (most recent call last):\n  File \"/codegendata/human-eval/human_eval/execution.py\", line 57, in unsafe_execute\n    exec(check_program, exec_globals)\n  File \"<string>\", line 250, in <module>\n  File \"<string>\", line 249, in test_0\n  File \"<string>\", line 44, in failure_to_exc_info\nAttributeError: 'ValueError' object has no attribute 'exc_info'\n", "passed": false}
{"task_id": 102, "prediction_id": 5, "generation": "def failure_to_exc_info(failure):\n    \"\"\"Extract exc_info from Failure instances\"\"\"\n    if isinstance(failure, Failure):\n        return failure.value.exc_info()\n    return None\n", "message": "failed: Traceback (most recent call last):\n  File \"/codegendata/human-eval/human_eval/execution.py\", line 57, in unsafe_execute\n    exec(check_program, exec_globals)\n  File \"<string>\", line 249, in <module>\n  File \"<string>\", line 248, in test_0\n  File \"<string>\", line 44, in failure_to_exc_info\nAttributeError: 'ValueError' object has no attribute 'exc_info'\n", "passed": false}
{"task_id": 102, "prediction_id": 6, "generation": "def failure_to_exc_info(failure):\n    \"\"\"Extract exc_info from Failure instances\"\"\"\n    if isinstance(failure, Failure):\n        return failure.value.exc_info()\n    return None\n", "message": "failed: Traceback (most recent call last):\n  File \"/codegendata/human-eval/human_eval/execution.py\", line 57, in unsafe_execute\n    exec(check_program, exec_globals)\n  File \"<string>\", line 249, in <module>\n  File \"<string>\", line 248, in test_0\n  File \"<string>\", line 44, in failure_to_exc_info\nAttributeError: 'ValueError' object has no attribute 'exc_info'\n", "passed": false}
{"task_id": 102, "prediction_id": 7, "generation": "def failure_to_exc_info(failure):\n    \"\"\"Extract exc_info from Failure instances\"\"\"\n    if isinstance(failure, Failure):\n        return failure.value.exc_info()\n    return None\n", "message": "failed: Traceback (most recent call last):\n  File \"/codegendata/human-eval/human_eval/execution.py\", line 57, in unsafe_execute\n    exec(check_program, exec_globals)\n  File \"<string>\", line 249, in <module>\n  File \"<string>\", line 248, in test_0\n  File \"<string>\", line 44, in failure_to_exc_info\nAttributeError: 'ValueError' object has no attribute 'exc_info'\n", "passed": false}
{"task_id": 102, "prediction_id": 8, "generation": "def failure_to_exc_info(failure):\n    \"\"\"Extract exc_info from Failure instances\"\"\"\n    if isinstance(failure, Failure):\n        return failure.value.exc_info()\n    else:\n        return failure\n", "message": "failed: Traceback (most recent call last):\n  File \"/codegendata/human-eval/human_eval/execution.py\", line 57, in unsafe_execute\n    exec(check_program, exec_globals)\n  File \"<string>\", line 250, in <module>\n  File \"<string>\", line 249, in test_0\n  File \"<string>\", line 44, in failure_to_exc_info\nAttributeError: 'ValueError' object has no attribute 'exc_info'\n", "passed": false}
{"task_id": 102, "prediction_id": 9, "generation": "def failure_to_exc_info(failure):\n    \"\"\"Extract exc_info from Failure instances\"\"\"\n    if isinstance(failure, Failure):\n        return failure.value.exc_info()\n    return failure\n", "message": "failed: Traceback (most recent call last):\n  File \"/codegendata/human-eval/human_eval/execution.py\", line 57, in unsafe_execute\n    exec(check_program, exec_globals)\n  File \"<string>\", line 249, in <module>\n  File \"<string>\", line 248, in test_0\n  File \"<string>\", line 44, in failure_to_exc_info\nAttributeError: 'ValueError' object has no attribute 'exc_info'\n", "passed": false}
{"task_id": 102, "prediction_id": 10, "generation": "def failure_to_exc_info(failure):\n    \"\"\"Extract exc_info from Failure instances\"\"\"\n    if isinstance(failure, Failure):\n        return failure.value.exc_info()\n    return failure\n", "message": "failed: Traceback (most recent call last):\n  File \"/codegendata/human-eval/human_eval/execution.py\", line 57, in unsafe_execute\n    exec(check_program, exec_globals)\n  File \"<string>\", line 249, in <module>\n  File \"<string>\", line 248, in test_0\n  File \"<string>\", line 44, in failure_to_exc_info\nAttributeError: 'ValueError' object has no attribute 'exc_info'\n", "passed": false}
{"task_id": 102, "prediction_id": 11, "generation": "def failure_to_exc_info(failure):\n    \"\"\"Extract exc_info from Failure instances\"\"\"\n    if isinstance(failure, Failure):\n        return failure.value.exc_info()\n    else:\n        return failure\n", "message": "failed: Traceback (most recent call last):\n  File \"/codegendata/human-eval/human_eval/execution.py\", line 57, in unsafe_execute\n    exec(check_program, exec_globals)\n  File \"<string>\", line 250, in <module>\n  File \"<string>\", line 249, in test_0\n  File \"<string>\", line 44, in failure_to_exc_info\nAttributeError: 'ValueError' object has no attribute 'exc_info'\n", "passed": false}
{"task_id": 102, "prediction_id": 12, "generation": "def failure_to_exc_info(failure):\n    \"\"\"Extract exc_info from Failure instances\"\"\"\n    if isinstance(failure, Failure):\n        return failure.value.exc_info()\n    return None\n", "message": "failed: Traceback (most recent call last):\n  File \"/codegendata/human-eval/human_eval/execution.py\", line 57, in unsafe_execute\n    exec(check_program, exec_globals)\n  File \"<string>\", line 249, in <module>\n  File \"<string>\", line 248, in test_0\n  File \"<string>\", line 44, in failure_to_exc_info\nAttributeError: 'ValueError' object has no attribute 'exc_info'\n", "passed": false}
{"task_id": 102, "prediction_id": 13, "generation": "def failure_to_exc_info(failure):\n    \"\"\"Extract exc_info from Failure instances\"\"\"\n    if isinstance(failure, Failure):\n        return failure.value.exc_info()\n    else:\n        return None\n", "message": "failed: Traceback (most recent call last):\n  File \"/codegendata/human-eval/human_eval/execution.py\", line 57, in unsafe_execute\n    exec(check_program, exec_globals)\n  File \"<string>\", line 250, in <module>\n  File \"<string>\", line 249, in test_0\n  File \"<string>\", line 44, in failure_to_exc_info\nAttributeError: 'ValueError' object has no attribute 'exc_info'\n", "passed": false}
{"task_id": 102, "prediction_id": 14, "generation": "def failure_to_exc_info(failure):\n    \"\"\"Extract exc_info from Failure instances\"\"\"\n    if isinstance(failure, Failure):\n        return failure.value.exc_info()\n    else:\n        return failure\n", "message": "failed: Traceback (most recent call last):\n  File \"/codegendata/human-eval/human_eval/execution.py\", line 57, in unsafe_execute\n    exec(check_program, exec_globals)\n  File \"<string>\", line 250, in <module>\n  File \"<string>\", line 249, in test_0\n  File \"<string>\", line 44, in failure_to_exc_info\nAttributeError: 'ValueError' object has no attribute 'exc_info'\n", "passed": false}
{"task_id": 102, "prediction_id": 15, "generation": "def failure_to_exc_info(failure):\n    \"\"\"Extract exc_info from Failure instances\"\"\"\n    if isinstance(failure, Failure):\n        return failure.value.exc_info()\n    else:\n        return failure\n", "message": "failed: Traceback (most recent call last):\n  File \"/codegendata/human-eval/human_eval/execution.py\", line 57, in unsafe_execute\n    exec(check_program, exec_globals)\n  File \"<string>\", line 250, in <module>\n  File \"<string>\", line 249, in test_0\n  File \"<string>\", line 44, in failure_to_exc_info\nAttributeError: 'ValueError' object has no attribute 'exc_info'\n", "passed": false}
{"task_id": 102, "prediction_id": 16, "generation": "def failure_to_exc_info(failure):\n    \"\"\"Extract exc_info from Failure instances\"\"\"\n    if isinstance(failure, Failure):\n        return failure.value.exc_info()\n    return None\n", "message": "failed: Traceback (most recent call last):\n  File \"/codegendata/human-eval/human_eval/execution.py\", line 57, in unsafe_execute\n    exec(check_program, exec_globals)\n  File \"<string>\", line 249, in <module>\n  File \"<string>\", line 248, in test_0\n  File \"<string>\", line 44, in failure_to_exc_info\nAttributeError: 'ValueError' object has no attribute 'exc_info'\n", "passed": false}
{"task_id": 102, "prediction_id": 17, "generation": "def failure_to_exc_info(failure):\n    \"\"\"Extract exc_info from Failure instances\"\"\"\n    if isinstance(failure, Failure):\n        return failure.value.exc_info()\n    return None\n", "message": "failed: Traceback (most recent call last):\n  File \"/codegendata/human-eval/human_eval/execution.py\", line 57, in unsafe_execute\n    exec(check_program, exec_globals)\n  File \"<string>\", line 249, in <module>\n  File \"<string>\", line 248, in test_0\n  File \"<string>\", line 44, in failure_to_exc_info\nAttributeError: 'ValueError' object has no attribute 'exc_info'\n", "passed": false}
{"task_id": 102, "prediction_id": 18, "generation": "def failure_to_exc_info(failure):\n    \"\"\"Extract exc_info from Failure instances\"\"\"\n    if isinstance(failure, Failure):\n        return failure.value.exc_info()\n    return None\n", "message": "failed: Traceback (most recent call last):\n  File \"/codegendata/human-eval/human_eval/execution.py\", line 57, in unsafe_execute\n    exec(check_program, exec_globals)\n  File \"<string>\", line 249, in <module>\n  File \"<string>\", line 248, in test_0\n  File \"<string>\", line 44, in failure_to_exc_info\nAttributeError: 'ValueError' object has no attribute 'exc_info'\n", "passed": false}
{"task_id": 102, "prediction_id": 19, "generation": "def failure_to_exc_info(failure):\n    \"\"\"Extract exc_info from Failure instances\"\"\"\n    if isinstance(failure, Failure):\n        return failure.value.exc_info()\n    else:\n        return failure\n", "message": "failed: Traceback (most recent call last):\n  File \"/codegendata/human-eval/human_eval/execution.py\", line 57, in unsafe_execute\n    exec(check_program, exec_globals)\n  File \"<string>\", line 250, in <module>\n  File \"<string>\", line 249, in test_0\n  File \"<string>\", line 44, in failure_to_exc_info\nAttributeError: 'ValueError' object has no attribute 'exc_info'\n", "passed": false}
{"task_id": 102, "prediction_id": 20, "generation": "def failure_to_exc_info(failure):\n    \"\"\"Extract exc_info from Failure instances\"\"\"\n    if isinstance(failure, Failure):\n        return failure.value.exc_info()\n    else:\n        return failure\n", "message": "failed: Traceback (most recent call last):\n  File \"/codegendata/human-eval/human_eval/execution.py\", line 57, in unsafe_execute\n    exec(check_program, exec_globals)\n  File \"<string>\", line 250, in <module>\n  File \"<string>\", line 249, in test_0\n  File \"<string>\", line 44, in failure_to_exc_info\nAttributeError: 'ValueError' object has no attribute 'exc_info'\n", "passed": false}
{"task_id": 102, "prediction_id": 21, "generation": "def failure_to_exc_info(failure):\n    \"\"\"Extract exc_info from Failure instances\"\"\"\n    if isinstance(failure, Failure):\n        return failure.value.exc_info()\n    else:\n        return sys.exc_info()\n", "message": "failed: Traceback (most recent call last):\n  File \"/codegendata/human-eval/human_eval/execution.py\", line 57, in unsafe_execute\n    exec(check_program, exec_globals)\n  File \"<string>\", line 250, in <module>\n  File \"<string>\", line 249, in test_0\n  File \"<string>\", line 44, in failure_to_exc_info\nAttributeError: 'ValueError' object has no attribute 'exc_info'\n", "passed": false}
{"task_id": 102, "prediction_id": 22, "generation": "def failure_to_exc_info(failure):\n    \"\"\"Extract exc_info from Failure instances\"\"\"\n    if isinstance(failure, Failure):\n        return failure.value.exc_info()\n    else:\n        return failure\n", "message": "failed: Traceback (most recent call last):\n  File \"/codegendata/human-eval/human_eval/execution.py\", line 57, in unsafe_execute\n    exec(check_program, exec_globals)\n  File \"<string>\", line 250, in <module>\n  File \"<string>\", line 249, in test_0\n  File \"<string>\", line 44, in failure_to_exc_info\nAttributeError: 'ValueError' object has no attribute 'exc_info'\n", "passed": false}
{"task_id": 102, "prediction_id": 23, "generation": "def failure_to_exc_info(failure):\n    \"\"\"Extract exc_info from Failure instances\"\"\"\n    if isinstance(failure, Failure):\n        return failure.value.exc_info()\n    else:\n        return failure\n", "message": "failed: Traceback (most recent call last):\n  File \"/codegendata/human-eval/human_eval/execution.py\", line 57, in unsafe_execute\n    exec(check_program, exec_globals)\n  File \"<string>\", line 250, in <module>\n  File \"<string>\", line 249, in test_0\n  File \"<string>\", line 44, in failure_to_exc_info\nAttributeError: 'ValueError' object has no attribute 'exc_info'\n", "passed": false}
{"task_id": 102, "prediction_id": 24, "generation": "def failure_to_exc_info(failure):\n    \"\"\"Extract exc_info from Failure instances\"\"\"\n    if isinstance(failure, Failure):\n        return failure.value.exc_info()\n    else:\n        return failure\n", "message": "failed: Traceback (most recent call last):\n  File \"/codegendata/human-eval/human_eval/execution.py\", line 57, in unsafe_execute\n    exec(check_program, exec_globals)\n  File \"<string>\", line 250, in <module>\n  File \"<string>\", line 249, in test_0\n  File \"<string>\", line 44, in failure_to_exc_info\nAttributeError: 'ValueError' object has no attribute 'exc_info'\n", "passed": false}
{"task_id": 102, "prediction_id": 25, "generation": "def failure_to_exc_info(failure):\n    \"\"\"Extract exc_info from Failure instances\"\"\"\n    if isinstance(failure, Failure):\n        return failure.value.exc_info()\n    return None\n", "message": "failed: Traceback (most recent call last):\n  File \"/codegendata/human-eval/human_eval/execution.py\", line 57, in unsafe_execute\n    exec(check_program, exec_globals)\n  File \"<string>\", line 249, in <module>\n  File \"<string>\", line 248, in test_0\n  File \"<string>\", line 44, in failure_to_exc_info\nAttributeError: 'ValueError' object has no attribute 'exc_info'\n", "passed": false}
{"task_id": 102, "prediction_id": 26, "generation": "def failure_to_exc_info(failure):\n    \"\"\"Extract exc_info from Failure instances\"\"\"\n    if isinstance(failure, Failure):\n        return failure.value.exc_info()\n    return None\n", "message": "failed: Traceback (most recent call last):\n  File \"/codegendata/human-eval/human_eval/execution.py\", line 57, in unsafe_execute\n    exec(check_program, exec_globals)\n  File \"<string>\", line 249, in <module>\n  File \"<string>\", line 248, in test_0\n  File \"<string>\", line 44, in failure_to_exc_info\nAttributeError: 'ValueError' object has no attribute 'exc_info'\n", "passed": false}
{"task_id": 102, "prediction_id": 27, "generation": "def failure_to_exc_info(failure):\n    \"\"\"Extract exc_info from Failure instances\"\"\"\n    if isinstance(failure, Failure):\n        return failure.value.exc_info()\n    else:\n        return failure\n", "message": "failed: Traceback (most recent call last):\n  File \"/codegendata/human-eval/human_eval/execution.py\", line 57, in unsafe_execute\n    exec(check_program, exec_globals)\n  File \"<string>\", line 250, in <module>\n  File \"<string>\", line 249, in test_0\n  File \"<string>\", line 44, in failure_to_exc_info\nAttributeError: 'ValueError' object has no attribute 'exc_info'\n", "passed": false}
{"task_id": 102, "prediction_id": 28, "generation": "def failure_to_exc_info(failure):\n    \"\"\"Extract exc_info from Failure instances\"\"\"\n    if isinstance(failure, Failure):\n        return failure.value.exc_info()\n    return None\n", "message": "failed: Traceback (most recent call last):\n  File \"/codegendata/human-eval/human_eval/execution.py\", line 57, in unsafe_execute\n    exec(check_program, exec_globals)\n  File \"<string>\", line 249, in <module>\n  File \"<string>\", line 248, in test_0\n  File \"<string>\", line 44, in failure_to_exc_info\nAttributeError: 'ValueError' object has no attribute 'exc_info'\n", "passed": false}
{"task_id": 102, "prediction_id": 29, "generation": "def failure_to_exc_info(failure):\n    \"\"\"Extract exc_info from Failure instances\"\"\"\n    if isinstance(failure, Failure):\n        return failure.value.exc_info()\n    return None\n", "message": "failed: Traceback (most recent call last):\n  File \"/codegendata/human-eval/human_eval/execution.py\", line 57, in unsafe_execute\n    exec(check_program, exec_globals)\n  File \"<string>\", line 249, in <module>\n  File \"<string>\", line 248, in test_0\n  File \"<string>\", line 44, in failure_to_exc_info\nAttributeError: 'ValueError' object has no attribute 'exc_info'\n", "passed": false}
{"task_id": 102, "prediction_id": 30, "generation": "def failure_to_exc_info(failure):\n    \"\"\"Extract exc_info from Failure instances\"\"\"\n    if isinstance(failure, Failure):\n        return failure.value.exc_info()\n    else:\n        return failure\n", "message": "failed: Traceback (most recent call last):\n  File \"/codegendata/human-eval/human_eval/execution.py\", line 57, in unsafe_execute\n    exec(check_program, exec_globals)\n  File \"<string>\", line 250, in <module>\n  File \"<string>\", line 249, in test_0\n  File \"<string>\", line 44, in failure_to_exc_info\nAttributeError: 'ValueError' object has no attribute 'exc_info'\n", "passed": false}
{"task_id": 102, "prediction_id": 31, "generation": "def failure_to_exc_info(failure):\n    \"\"\"Extract exc_info from Failure instances\"\"\"\n    if isinstance(failure, Failure):\n        return failure.value.exc_info()\n    return None\n", "message": "failed: Traceback (most recent call last):\n  File \"/codegendata/human-eval/human_eval/execution.py\", line 57, in unsafe_execute\n    exec(check_program, exec_globals)\n  File \"<string>\", line 249, in <module>\n  File \"<string>\", line 248, in test_0\n  File \"<string>\", line 44, in failure_to_exc_info\nAttributeError: 'ValueError' object has no attribute 'exc_info'\n", "passed": false}
{"task_id": 102, "prediction_id": 32, "generation": "def failure_to_exc_info(failure):\n    \"\"\"Extract exc_info from Failure instances\"\"\"\n    if isinstance(failure, Failure):\n        return failure.value.exc_info()\n    return None\n", "message": "failed: Traceback (most recent call last):\n  File \"/codegendata/human-eval/human_eval/execution.py\", line 57, in unsafe_execute\n    exec(check_program, exec_globals)\n  File \"<string>\", line 249, in <module>\n  File \"<string>\", line 248, in test_0\n  File \"<string>\", line 44, in failure_to_exc_info\nAttributeError: 'ValueError' object has no attribute 'exc_info'\n", "passed": false}
{"task_id": 102, "prediction_id": 33, "generation": "def failure_to_exc_info(failure):\n    \"\"\"Extract exc_info from Failure instances\"\"\"\n    if isinstance(failure, Failure):\n        return failure.value.exc_info()\n    return None\n", "message": "failed: Traceback (most recent call last):\n  File \"/codegendata/human-eval/human_eval/execution.py\", line 57, in unsafe_execute\n    exec(check_program, exec_globals)\n  File \"<string>\", line 249, in <module>\n  File \"<string>\", line 248, in test_0\n  File \"<string>\", line 44, in failure_to_exc_info\nAttributeError: 'ValueError' object has no attribute 'exc_info'\n", "passed": false}
{"task_id": 102, "prediction_id": 34, "generation": "def failure_to_exc_info(failure):\n    \"\"\"Extract exc_info from Failure instances\"\"\"\n    if isinstance(failure, Failure):\n        return failure.value.exc_info()\n    else:\n        return failure\n", "message": "failed: Traceback (most recent call last):\n  File \"/codegendata/human-eval/human_eval/execution.py\", line 57, in unsafe_execute\n    exec(check_program, exec_globals)\n  File \"<string>\", line 250, in <module>\n  File \"<string>\", line 249, in test_0\n  File \"<string>\", line 44, in failure_to_exc_info\nAttributeError: 'ValueError' object has no attribute 'exc_info'\n", "passed": false}
{"task_id": 102, "prediction_id": 35, "generation": "def failure_to_exc_info(failure):\n    \"\"\"Extract exc_info from Failure instances\"\"\"\n    if isinstance(failure, Failure):\n        return failure.value.exc_info()\n    return None\n", "message": "failed: Traceback (most recent call last):\n  File \"/codegendata/human-eval/human_eval/execution.py\", line 57, in unsafe_execute\n    exec(check_program, exec_globals)\n  File \"<string>\", line 249, in <module>\n  File \"<string>\", line 248, in test_0\n  File \"<string>\", line 44, in failure_to_exc_info\nAttributeError: 'ValueError' object has no attribute 'exc_info'\n", "passed": false}
{"task_id": 102, "prediction_id": 36, "generation": "def failure_to_exc_info(failure):\n    \"\"\"Extract exc_info from Failure instances\"\"\"\n    if isinstance(failure, Failure):\n        return failure.value.exc_info()\n    return None\n", "message": "failed: Traceback (most recent call last):\n  File \"/codegendata/human-eval/human_eval/execution.py\", line 57, in unsafe_execute\n    exec(check_program, exec_globals)\n  File \"<string>\", line 249, in <module>\n  File \"<string>\", line 248, in test_0\n  File \"<string>\", line 44, in failure_to_exc_info\nAttributeError: 'ValueError' object has no attribute 'exc_info'\n", "passed": false}
{"task_id": 102, "prediction_id": 37, "generation": "def failure_to_exc_info(failure):\n    \"\"\"Extract exc_info from Failure instances\"\"\"\n    if isinstance(failure, Failure):\n        return failure.value.exc_info()\n    return failure\n", "message": "failed: Traceback (most recent call last):\n  File \"/codegendata/human-eval/human_eval/execution.py\", line 57, in unsafe_execute\n    exec(check_program, exec_globals)\n  File \"<string>\", line 249, in <module>\n  File \"<string>\", line 248, in test_0\n  File \"<string>\", line 44, in failure_to_exc_info\nAttributeError: 'ValueError' object has no attribute 'exc_info'\n", "passed": false}
{"task_id": 102, "prediction_id": 38, "generation": "def failure_to_exc_info(failure):\n    \"\"\"Extract exc_info from Failure instances\"\"\"\n    if isinstance(failure, Failure):\n        return failure.value.exc_info()\n    else:\n        return failure\n", "message": "failed: Traceback (most recent call last):\n  File \"/codegendata/human-eval/human_eval/execution.py\", line 57, in unsafe_execute\n    exec(check_program, exec_globals)\n  File \"<string>\", line 250, in <module>\n  File \"<string>\", line 249, in test_0\n  File \"<string>\", line 44, in failure_to_exc_info\nAttributeError: 'ValueError' object has no attribute 'exc_info'\n", "passed": false}
{"task_id": 102, "prediction_id": 39, "generation": "def failure_to_exc_info(failure):\n    \"\"\"Extract exc_info from Failure instances\"\"\"\n    if isinstance(failure, Failure):\n        return failure.value.exc_info()\n    else:\n        return sys.exc_info()\n", "message": "failed: Traceback (most recent call last):\n  File \"/codegendata/human-eval/human_eval/execution.py\", line 57, in unsafe_execute\n    exec(check_program, exec_globals)\n  File \"<string>\", line 250, in <module>\n  File \"<string>\", line 249, in test_0\n  File \"<string>\", line 44, in failure_to_exc_info\nAttributeError: 'ValueError' object has no attribute 'exc_info'\n", "passed": false}
{"task_id": 102, "prediction_id": 40, "generation": "def failure_to_exc_info(failure):\n    \"\"\"Extract exc_info from Failure instances\"\"\"\n    if isinstance(failure, Failure):\n        return failure.value.exc_info()\n    return None\n", "message": "failed: Traceback (most recent call last):\n  File \"/codegendata/human-eval/human_eval/execution.py\", line 57, in unsafe_execute\n    exec(check_program, exec_globals)\n  File \"<string>\", line 249, in <module>\n  File \"<string>\", line 248, in test_0\n  File \"<string>\", line 44, in failure_to_exc_info\nAttributeError: 'ValueError' object has no attribute 'exc_info'\n", "passed": false}
{"task_id": 102, "prediction_id": 41, "generation": "def failure_to_exc_info(failure):\n    \"\"\"Extract exc_info from Failure instances\"\"\"\n    if isinstance(failure, Failure):\n        return failure.value.exc_info()\n    else:\n        return None\n", "message": "failed: Traceback (most recent call last):\n  File \"/codegendata/human-eval/human_eval/execution.py\", line 57, in unsafe_execute\n    exec(check_program, exec_globals)\n  File \"<string>\", line 250, in <module>\n  File \"<string>\", line 249, in test_0\n  File \"<string>\", line 44, in failure_to_exc_info\nAttributeError: 'ValueError' object has no attribute 'exc_info'\n", "passed": false}
{"task_id": 102, "prediction_id": 42, "generation": "def failure_to_exc_info(failure):\n    \"\"\"Extract exc_info from Failure instances\"\"\"\n    if isinstance(failure, Failure):\n        return failure.value.exc_info()\n    return None\n", "message": "failed: Traceback (most recent call last):\n  File \"/codegendata/human-eval/human_eval/execution.py\", line 57, in unsafe_execute\n    exec(check_program, exec_globals)\n  File \"<string>\", line 249, in <module>\n  File \"<string>\", line 248, in test_0\n  File \"<string>\", line 44, in failure_to_exc_info\nAttributeError: 'ValueError' object has no attribute 'exc_info'\n", "passed": false}
{"task_id": 102, "prediction_id": 43, "generation": "def failure_to_exc_info(failure):\n    \"\"\"Extract exc_info from Failure instances\"\"\"\n    if isinstance(failure, Failure):\n        return failure.value.exc_info()\n    else:\n        return failure\n", "message": "failed: Traceback (most recent call last):\n  File \"/codegendata/human-eval/human_eval/execution.py\", line 57, in unsafe_execute\n    exec(check_program, exec_globals)\n  File \"<string>\", line 250, in <module>\n  File \"<string>\", line 249, in test_0\n  File \"<string>\", line 44, in failure_to_exc_info\nAttributeError: 'ValueError' object has no attribute 'exc_info'\n", "passed": false}
{"task_id": 102, "prediction_id": 44, "generation": "def failure_to_exc_info(failure):\n    \"\"\"Extract exc_info from Failure instances\"\"\"\n    if isinstance(failure, Failure):\n        return failure.value.exc_info()\n    return None\n", "message": "failed: Traceback (most recent call last):\n  File \"/codegendata/human-eval/human_eval/execution.py\", line 57, in unsafe_execute\n    exec(check_program, exec_globals)\n  File \"<string>\", line 249, in <module>\n  File \"<string>\", line 248, in test_0\n  File \"<string>\", line 44, in failure_to_exc_info\nAttributeError: 'ValueError' object has no attribute 'exc_info'\n", "passed": false}
{"task_id": 102, "prediction_id": 45, "generation": "def failure_to_exc_info(failure):\n    \"\"\"Extract exc_info from Failure instances\"\"\"\n    if isinstance(failure, Failure):\n        return failure.value.exc_info()\n    else:\n        return failure\n", "message": "failed: Traceback (most recent call last):\n  File \"/codegendata/human-eval/human_eval/execution.py\", line 57, in unsafe_execute\n    exec(check_program, exec_globals)\n  File \"<string>\", line 250, in <module>\n  File \"<string>\", line 249, in test_0\n  File \"<string>\", line 44, in failure_to_exc_info\nAttributeError: 'ValueError' object has no attribute 'exc_info'\n", "passed": false}
{"task_id": 102, "prediction_id": 46, "generation": "def failure_to_exc_info(failure):\n    \"\"\"Extract exc_info from Failure instances\"\"\"\n    if isinstance(failure, Failure):\n        return failure.value.exc_info()\n    else:\n        return failure\n", "message": "failed: Traceback (most recent call last):\n  File \"/codegendata/human-eval/human_eval/execution.py\", line 57, in unsafe_execute\n    exec(check_program, exec_globals)\n  File \"<string>\", line 250, in <module>\n  File \"<string>\", line 249, in test_0\n  File \"<string>\", line 44, in failure_to_exc_info\nAttributeError: 'ValueError' object has no attribute 'exc_info'\n", "passed": false}
{"task_id": 102, "prediction_id": 47, "generation": "def failure_to_exc_info(failure):\n    \"\"\"Extract exc_info from Failure instances\"\"\"\n    if isinstance(failure, Failure):\n        return failure.value.exc_info()\n    else:\n        return failure\n", "message": "failed: Traceback (most recent call last):\n  File \"/codegendata/human-eval/human_eval/execution.py\", line 57, in unsafe_execute\n    exec(check_program, exec_globals)\n  File \"<string>\", line 250, in <module>\n  File \"<string>\", line 249, in test_0\n  File \"<string>\", line 44, in failure_to_exc_info\nAttributeError: 'ValueError' object has no attribute 'exc_info'\n", "passed": false}
{"task_id": 102, "prediction_id": 48, "generation": "def failure_to_exc_info(failure):\n    \"\"\"Extract exc_info from Failure instances\"\"\"\n    if isinstance(failure, Failure):\n        return failure.value.exc_info()\n    return None\n", "message": "failed: Traceback (most recent call last):\n  File \"/codegendata/human-eval/human_eval/execution.py\", line 57, in unsafe_execute\n    exec(check_program, exec_globals)\n  File \"<string>\", line 249, in <module>\n  File \"<string>\", line 248, in test_0\n  File \"<string>\", line 44, in failure_to_exc_info\nAttributeError: 'ValueError' object has no attribute 'exc_info'\n", "passed": false}
{"task_id": 102, "prediction_id": 49, "generation": "def failure_to_exc_info(failure):\n    \"\"\"Extract exc_info from Failure instances\"\"\"\n    if isinstance(failure, Failure):\n        return failure.value.exc_info()\n    return failure\n", "message": "failed: Traceback (most recent call last):\n  File \"/codegendata/human-eval/human_eval/execution.py\", line 57, in unsafe_execute\n    exec(check_program, exec_globals)\n  File \"<string>\", line 249, in <module>\n  File \"<string>\", line 248, in test_0\n  File \"<string>\", line 44, in failure_to_exc_info\nAttributeError: 'ValueError' object has no attribute 'exc_info'\n", "passed": false}
