{"task_id": 257, "prediction_id": 0, "generation": "def _attr(obj: object, attr: str) -> object:\n    \"\"\"Nest `getattr` function.\"\"\"\n    return getattr(getattr(obj, attr), attr)\n", "message": "failed: Traceback (most recent call last):\n  File \"/codegendata/human-eval/human_eval/execution.py\", line 57, in unsafe_execute\n    exec(check_program, exec_globals)\n  File \"<string>\", line 626, in <module>\n  File \"<string>\", line 625, in test_0\n  File \"<string>\", line 59, in _attr\nAttributeError: 'int' object has no attribute 'a.'\n", "passed": false}
{"task_id": 257, "prediction_id": 1, "generation": "def _attr(obj: object, attr: str) -> object:\n    \"\"\"Nest `getattr` function.\"\"\"\n    return getattr(getattr(obj, attr), attr)\n", "message": "failed: Traceback (most recent call last):\n  File \"/codegendata/human-eval/human_eval/execution.py\", line 57, in unsafe_execute\n    exec(check_program, exec_globals)\n  File \"<string>\", line 626, in <module>\n  File \"<string>\", line 625, in test_0\n  File \"<string>\", line 59, in _attr\nAttributeError: 'int' object has no attribute 'a.'\n", "passed": false}
{"task_id": 257, "prediction_id": 2, "generation": "def _attr(obj: object, attr: str) -> object:\n    \"\"\"Nest `getattr` function.\"\"\"\n    return getattr(getattr(obj, attr), attr)\n", "message": "failed: Traceback (most recent call last):\n  File \"/codegendata/human-eval/human_eval/execution.py\", line 57, in unsafe_execute\n    exec(check_program, exec_globals)\n  File \"<string>\", line 626, in <module>\n  File \"<string>\", line 625, in test_0\n  File \"<string>\", line 59, in _attr\nAttributeError: 'int' object has no attribute 'a.'\n", "passed": false}
{"task_id": 257, "prediction_id": 3, "generation": "def _attr(obj: object, attr: str) -> object:\n    \"\"\"Nest `getattr` function.\"\"\"\n    return getattr(getattr(obj, attr), attr)\n", "message": "failed: Traceback (most recent call last):\n  File \"/codegendata/human-eval/human_eval/execution.py\", line 57, in unsafe_execute\n    exec(check_program, exec_globals)\n  File \"<string>\", line 626, in <module>\n  File \"<string>\", line 625, in test_0\n  File \"<string>\", line 59, in _attr\nAttributeError: 'int' object has no attribute 'a.'\n", "passed": false}
{"task_id": 257, "prediction_id": 4, "generation": "def _attr(obj: object, attr: str) -> object:\n    \"\"\"Nest `getattr` function.\"\"\"\n    return getattr(getattr(obj, attr), attr)\n", "message": "failed: Traceback (most recent call last):\n  File \"/codegendata/human-eval/human_eval/execution.py\", line 57, in unsafe_execute\n    exec(check_program, exec_globals)\n  File \"<string>\", line 626, in <module>\n  File \"<string>\", line 625, in test_0\n  File \"<string>\", line 59, in _attr\nAttributeError: 'int' object has no attribute 'a.'\n", "passed": false}
{"task_id": 257, "prediction_id": 5, "generation": "def _attr(obj: object, attr: str) -> object:\n    \"\"\"Nest `getattr` function.\"\"\"\n    return getattr(getattr(obj, attr), attr)\n", "message": "failed: Traceback (most recent call last):\n  File \"/codegendata/human-eval/human_eval/execution.py\", line 57, in unsafe_execute\n    exec(check_program, exec_globals)\n  File \"<string>\", line 626, in <module>\n  File \"<string>\", line 625, in test_0\n  File \"<string>\", line 59, in _attr\nAttributeError: 'int' object has no attribute 'a.'\n", "passed": false}
{"task_id": 257, "prediction_id": 6, "generation": "def _attr(obj: object, attr: str) -> object:\n    \"\"\"Nest `getattr` function.\"\"\"\n    return getattr(getattr(obj, attr), attr)\n", "message": "failed: Traceback (most recent call last):\n  File \"/codegendata/human-eval/human_eval/execution.py\", line 57, in unsafe_execute\n    exec(check_program, exec_globals)\n  File \"<string>\", line 626, in <module>\n  File \"<string>\", line 625, in test_0\n  File \"<string>\", line 59, in _attr\nAttributeError: 'int' object has no attribute 'a.'\n", "passed": false}
{"task_id": 257, "prediction_id": 7, "generation": "def _attr(obj: object, attr: str) -> object:\n    \"\"\"Nest `getattr` function.\"\"\"\n    return getattr(getattr(obj, attr), attr)\n", "message": "failed: Traceback (most recent call last):\n  File \"/codegendata/human-eval/human_eval/execution.py\", line 57, in unsafe_execute\n    exec(check_program, exec_globals)\n  File \"<string>\", line 626, in <module>\n  File \"<string>\", line 625, in test_0\n  File \"<string>\", line 59, in _attr\nAttributeError: 'int' object has no attribute 'a.'\n", "passed": false}
{"task_id": 257, "prediction_id": 8, "generation": "def _attr(obj: object, attr: str) -> object:\n    \"\"\"Nest `getattr` function.\"\"\"\n    return getattr(getattr(obj, attr), attr)\n", "message": "failed: Traceback (most recent call last):\n  File \"/codegendata/human-eval/human_eval/execution.py\", line 57, in unsafe_execute\n    exec(check_program, exec_globals)\n  File \"<string>\", line 626, in <module>\n  File \"<string>\", line 625, in test_0\n  File \"<string>\", line 59, in _attr\nAttributeError: 'int' object has no attribute 'a.'\n", "passed": false}
{"task_id": 257, "prediction_id": 9, "generation": "def _attr(obj: object, attr: str) -> object:\n    \"\"\"Nest `getattr` function.\"\"\"\n    return getattr(getattr(obj, attr), attr)\n", "message": "failed: Traceback (most recent call last):\n  File \"/codegendata/human-eval/human_eval/execution.py\", line 57, in unsafe_execute\n    exec(check_program, exec_globals)\n  File \"<string>\", line 626, in <module>\n  File \"<string>\", line 625, in test_0\n  File \"<string>\", line 59, in _attr\nAttributeError: 'int' object has no attribute 'a.'\n", "passed": false}
{"task_id": 257, "prediction_id": 10, "generation": "def _attr(obj: object, attr: str) -> object:\n    \"\"\"Nest `getattr` function.\"\"\"\n    return getattr(getattr(obj, attr), attr)\n", "message": "failed: Traceback (most recent call last):\n  File \"/codegendata/human-eval/human_eval/execution.py\", line 57, in unsafe_execute\n    exec(check_program, exec_globals)\n  File \"<string>\", line 626, in <module>\n  File \"<string>\", line 625, in test_0\n  File \"<string>\", line 59, in _attr\nAttributeError: 'int' object has no attribute 'a.'\n", "passed": false}
{"task_id": 257, "prediction_id": 11, "generation": "def _attr(obj: object, attr: str) -> object:\n    \"\"\"Nest `getattr` function.\"\"\"\n    return getattr(getattr(obj, attr), attr)\n", "message": "failed: Traceback (most recent call last):\n  File \"/codegendata/human-eval/human_eval/execution.py\", line 57, in unsafe_execute\n    exec(check_program, exec_globals)\n  File \"<string>\", line 626, in <module>\n  File \"<string>\", line 625, in test_0\n  File \"<string>\", line 59, in _attr\nAttributeError: 'int' object has no attribute 'a.'\n", "passed": false}
{"task_id": 257, "prediction_id": 12, "generation": "def _attr(obj: object, attr: str) -> object:\n    \"\"\"Nest `getattr` function.\"\"\"\n    return getattr(getattr(obj, attr), attr)\n", "message": "failed: Traceback (most recent call last):\n  File \"/codegendata/human-eval/human_eval/execution.py\", line 57, in unsafe_execute\n    exec(check_program, exec_globals)\n  File \"<string>\", line 626, in <module>\n  File \"<string>\", line 625, in test_0\n  File \"<string>\", line 59, in _attr\nAttributeError: 'int' object has no attribute 'a.'\n", "passed": false}
{"task_id": 257, "prediction_id": 13, "generation": "def _attr(obj: object, attr: str) -> object:\n    \"\"\"Nest `getattr` function.\"\"\"\n    return getattr(getattr(obj, attr), attr)\n", "message": "failed: Traceback (most recent call last):\n  File \"/codegendata/human-eval/human_eval/execution.py\", line 57, in unsafe_execute\n    exec(check_program, exec_globals)\n  File \"<string>\", line 626, in <module>\n  File \"<string>\", line 625, in test_0\n  File \"<string>\", line 59, in _attr\nAttributeError: 'int' object has no attribute 'a.'\n", "passed": false}
{"task_id": 257, "prediction_id": 14, "generation": "def _attr(obj: object, attr: str) -> object:\n    \"\"\"Nest `getattr` function.\"\"\"\n    return getattr(getattr(obj, attr), attr)\n", "message": "failed: Traceback (most recent call last):\n  File \"/codegendata/human-eval/human_eval/execution.py\", line 57, in unsafe_execute\n    exec(check_program, exec_globals)\n  File \"<string>\", line 626, in <module>\n  File \"<string>\", line 625, in test_0\n  File \"<string>\", line 59, in _attr\nAttributeError: 'int' object has no attribute 'a.'\n", "passed": false}
{"task_id": 257, "prediction_id": 15, "generation": "def _attr(obj: object, attr: str) -> object:\n    \"\"\"Nest `getattr` function.\"\"\"\n    return getattr(getattr(obj, attr), attr)\n", "message": "failed: Traceback (most recent call last):\n  File \"/codegendata/human-eval/human_eval/execution.py\", line 57, in unsafe_execute\n    exec(check_program, exec_globals)\n  File \"<string>\", line 626, in <module>\n  File \"<string>\", line 625, in test_0\n  File \"<string>\", line 59, in _attr\nAttributeError: 'int' object has no attribute 'a.'\n", "passed": false}
{"task_id": 257, "prediction_id": 16, "generation": "def _attr(obj: object, attr: str) -> object:\n    \"\"\"Nest `getattr` function.\"\"\"\n    return getattr(getattr(obj, attr), attr)\n", "message": "failed: Traceback (most recent call last):\n  File \"/codegendata/human-eval/human_eval/execution.py\", line 57, in unsafe_execute\n    exec(check_program, exec_globals)\n  File \"<string>\", line 626, in <module>\n  File \"<string>\", line 625, in test_0\n  File \"<string>\", line 59, in _attr\nAttributeError: 'int' object has no attribute 'a.'\n", "passed": false}
{"task_id": 257, "prediction_id": 17, "generation": "def _attr(obj: object, attr: str) -> object:\n    \"\"\"Nest `getattr` function.\"\"\"\n    return getattr(getattr(obj, attr), attr)\n", "message": "failed: Traceback (most recent call last):\n  File \"/codegendata/human-eval/human_eval/execution.py\", line 57, in unsafe_execute\n    exec(check_program, exec_globals)\n  File \"<string>\", line 626, in <module>\n  File \"<string>\", line 625, in test_0\n  File \"<string>\", line 59, in _attr\nAttributeError: 'int' object has no attribute 'a.'\n", "passed": false}
{"task_id": 257, "prediction_id": 18, "generation": "def _attr(obj: object, attr: str) -> object:\n    \"\"\"Nest `getattr` function.\"\"\"\n    return getattr(getattr(obj, attr), attr)\n", "message": "failed: Traceback (most recent call last):\n  File \"/codegendata/human-eval/human_eval/execution.py\", line 57, in unsafe_execute\n    exec(check_program, exec_globals)\n  File \"<string>\", line 626, in <module>\n  File \"<string>\", line 625, in test_0\n  File \"<string>\", line 59, in _attr\nAttributeError: 'int' object has no attribute 'a.'\n", "passed": false}
{"task_id": 257, "prediction_id": 19, "generation": "def _attr(obj: object, attr: str) -> object:\n    \"\"\"Nest `getattr` function.\"\"\"\n    return getattr(getattr(obj, attr), attr)\n", "message": "failed: Traceback (most recent call last):\n  File \"/codegendata/human-eval/human_eval/execution.py\", line 57, in unsafe_execute\n    exec(check_program, exec_globals)\n  File \"<string>\", line 626, in <module>\n  File \"<string>\", line 625, in test_0\n  File \"<string>\", line 59, in _attr\nAttributeError: 'int' object has no attribute 'a.'\n", "passed": false}
{"task_id": 257, "prediction_id": 20, "generation": "def _attr(obj: object, attr: str) -> object:\n    \"\"\"Nest `getattr` function.\"\"\"\n    return getattr(getattr(obj, attr), attr)\n", "message": "failed: Traceback (most recent call last):\n  File \"/codegendata/human-eval/human_eval/execution.py\", line 57, in unsafe_execute\n    exec(check_program, exec_globals)\n  File \"<string>\", line 626, in <module>\n  File \"<string>\", line 625, in test_0\n  File \"<string>\", line 59, in _attr\nAttributeError: 'int' object has no attribute 'a.'\n", "passed": false}
{"task_id": 257, "prediction_id": 21, "generation": "def _attr(obj: object, attr: str) -> object:\n    \"\"\"Nest `getattr` function.\"\"\"\n    return getattr(getattr(obj, attr), attr)\n", "message": "failed: Traceback (most recent call last):\n  File \"/codegendata/human-eval/human_eval/execution.py\", line 57, in unsafe_execute\n    exec(check_program, exec_globals)\n  File \"<string>\", line 626, in <module>\n  File \"<string>\", line 625, in test_0\n  File \"<string>\", line 59, in _attr\nAttributeError: 'int' object has no attribute 'a.'\n", "passed": false}
{"task_id": 257, "prediction_id": 22, "generation": "def _attr(obj: object, attr: str) -> object:\n    \"\"\"Nest `getattr` function.\"\"\"\n    return getattr(getattr(obj, attr), attr)\n", "message": "failed: Traceback (most recent call last):\n  File \"/codegendata/human-eval/human_eval/execution.py\", line 57, in unsafe_execute\n    exec(check_program, exec_globals)\n  File \"<string>\", line 626, in <module>\n  File \"<string>\", line 625, in test_0\n  File \"<string>\", line 59, in _attr\nAttributeError: 'int' object has no attribute 'a.'\n", "passed": false}
{"task_id": 257, "prediction_id": 23, "generation": "def _attr(obj: object, attr: str) -> object:\n    \"\"\"Nest `getattr` function.\"\"\"\n    return getattr(getattr(obj, attr), attr)\n", "message": "failed: Traceback (most recent call last):\n  File \"/codegendata/human-eval/human_eval/execution.py\", line 57, in unsafe_execute\n    exec(check_program, exec_globals)\n  File \"<string>\", line 626, in <module>\n  File \"<string>\", line 625, in test_0\n  File \"<string>\", line 59, in _attr\nAttributeError: 'int' object has no attribute 'a.'\n", "passed": false}
{"task_id": 257, "prediction_id": 24, "generation": "def _attr(obj: object, attr: str) -> object:\n    \"\"\"Nest `getattr` function.\"\"\"\n    return getattr(getattr(obj, attr), attr)\n", "message": "failed: Traceback (most recent call last):\n  File \"/codegendata/human-eval/human_eval/execution.py\", line 57, in unsafe_execute\n    exec(check_program, exec_globals)\n  File \"<string>\", line 626, in <module>\n  File \"<string>\", line 625, in test_0\n  File \"<string>\", line 59, in _attr\nAttributeError: 'int' object has no attribute 'a.'\n", "passed": false}
{"task_id": 257, "prediction_id": 25, "generation": "def _attr(obj: object, attr: str) -> object:\n    \"\"\"Nest `getattr` function.\"\"\"\n    return getattr(getattr(obj, attr), attr)\n", "message": "failed: Traceback (most recent call last):\n  File \"/codegendata/human-eval/human_eval/execution.py\", line 57, in unsafe_execute\n    exec(check_program, exec_globals)\n  File \"<string>\", line 626, in <module>\n  File \"<string>\", line 625, in test_0\n  File \"<string>\", line 59, in _attr\nAttributeError: 'int' object has no attribute 'a.'\n", "passed": false}
{"task_id": 257, "prediction_id": 26, "generation": "def _attr(obj: object, attr: str) -> object:\n    \"\"\"Nest `getattr` function.\"\"\"\n    return getattr(getattr(obj, attr), attr)\n", "message": "failed: Traceback (most recent call last):\n  File \"/codegendata/human-eval/human_eval/execution.py\", line 57, in unsafe_execute\n    exec(check_program, exec_globals)\n  File \"<string>\", line 626, in <module>\n  File \"<string>\", line 625, in test_0\n  File \"<string>\", line 59, in _attr\nAttributeError: 'int' object has no attribute 'a.'\n", "passed": false}
{"task_id": 257, "prediction_id": 27, "generation": "def _attr(obj: object, attr: str) -> object:\n    \"\"\"Nest `getattr` function.\"\"\"\n    return getattr(getattr(obj, attr), attr)\n", "message": "failed: Traceback (most recent call last):\n  File \"/codegendata/human-eval/human_eval/execution.py\", line 57, in unsafe_execute\n    exec(check_program, exec_globals)\n  File \"<string>\", line 626, in <module>\n  File \"<string>\", line 625, in test_0\n  File \"<string>\", line 59, in _attr\nAttributeError: 'int' object has no attribute 'a.'\n", "passed": false}
{"task_id": 257, "prediction_id": 28, "generation": "def _attr(obj: object, attr: str) -> object:\n    \"\"\"Nest `getattr` function.\"\"\"\n    return getattr(getattr(obj, attr), attr)\n", "message": "failed: Traceback (most recent call last):\n  File \"/codegendata/human-eval/human_eval/execution.py\", line 57, in unsafe_execute\n    exec(check_program, exec_globals)\n  File \"<string>\", line 626, in <module>\n  File \"<string>\", line 625, in test_0\n  File \"<string>\", line 59, in _attr\nAttributeError: 'int' object has no attribute 'a.'\n", "passed": false}
{"task_id": 257, "prediction_id": 29, "generation": "def _attr(obj: object, attr: str) -> object:\n    \"\"\"Nest `getattr` function.\"\"\"\n    return getattr(getattr(obj, attr), attr)\n", "message": "failed: Traceback (most recent call last):\n  File \"/codegendata/human-eval/human_eval/execution.py\", line 57, in unsafe_execute\n    exec(check_program, exec_globals)\n  File \"<string>\", line 626, in <module>\n  File \"<string>\", line 625, in test_0\n  File \"<string>\", line 59, in _attr\nAttributeError: 'int' object has no attribute 'a.'\n", "passed": false}
{"task_id": 257, "prediction_id": 30, "generation": "def _attr(obj: object, attr: str) -> object:\n    \"\"\"Nest `getattr` function.\"\"\"\n    return getattr(getattr(obj, attr), attr)\n", "message": "failed: Traceback (most recent call last):\n  File \"/codegendata/human-eval/human_eval/execution.py\", line 57, in unsafe_execute\n    exec(check_program, exec_globals)\n  File \"<string>\", line 626, in <module>\n  File \"<string>\", line 625, in test_0\n  File \"<string>\", line 59, in _attr\nAttributeError: 'int' object has no attribute 'a.'\n", "passed": false}
{"task_id": 257, "prediction_id": 31, "generation": "def _attr(obj: object, attr: str) -> object:\n    \"\"\"Nest `getattr` function.\"\"\"\n    return getattr(getattr(obj, attr), attr)\n", "message": "failed: Traceback (most recent call last):\n  File \"/codegendata/human-eval/human_eval/execution.py\", line 57, in unsafe_execute\n    exec(check_program, exec_globals)\n  File \"<string>\", line 626, in <module>\n  File \"<string>\", line 625, in test_0\n  File \"<string>\", line 59, in _attr\nAttributeError: 'int' object has no attribute 'a.'\n", "passed": false}
{"task_id": 257, "prediction_id": 32, "generation": "def _attr(obj: object, attr: str) -> object:\n    \"\"\"Nest `getattr` function.\"\"\"\n    return getattr(getattr(obj, attr), attr)\n", "message": "failed: Traceback (most recent call last):\n  File \"/codegendata/human-eval/human_eval/execution.py\", line 57, in unsafe_execute\n    exec(check_program, exec_globals)\n  File \"<string>\", line 626, in <module>\n  File \"<string>\", line 625, in test_0\n  File \"<string>\", line 59, in _attr\nAttributeError: 'int' object has no attribute 'a.'\n", "passed": false}
{"task_id": 257, "prediction_id": 33, "generation": "def _attr(obj: object, attr: str) -> object:\n    \"\"\"Nest `getattr` function.\"\"\"\n    return getattr(getattr(obj, attr), attr)\n", "message": "failed: Traceback (most recent call last):\n  File \"/codegendata/human-eval/human_eval/execution.py\", line 57, in unsafe_execute\n    exec(check_program, exec_globals)\n  File \"<string>\", line 626, in <module>\n  File \"<string>\", line 625, in test_0\n  File \"<string>\", line 59, in _attr\nAttributeError: 'int' object has no attribute 'a.'\n", "passed": false}
{"task_id": 257, "prediction_id": 34, "generation": "def _attr(obj: object, attr: str) -> object:\n    \"\"\"Nest `getattr` function.\"\"\"\n    return getattr(getattr(obj, attr), attr)\n", "message": "failed: Traceback (most recent call last):\n  File \"/codegendata/human-eval/human_eval/execution.py\", line 57, in unsafe_execute\n    exec(check_program, exec_globals)\n  File \"<string>\", line 626, in <module>\n  File \"<string>\", line 625, in test_0\n  File \"<string>\", line 59, in _attr\nAttributeError: 'int' object has no attribute 'a.'\n", "passed": false}
{"task_id": 257, "prediction_id": 35, "generation": "def _attr(obj: object, attr: str) -> object:\n    \"\"\"Nest `getattr` function.\"\"\"\n    return getattr(getattr(obj, attr), attr)\n", "message": "failed: Traceback (most recent call last):\n  File \"/codegendata/human-eval/human_eval/execution.py\", line 57, in unsafe_execute\n    exec(check_program, exec_globals)\n  File \"<string>\", line 626, in <module>\n  File \"<string>\", line 625, in test_0\n  File \"<string>\", line 59, in _attr\nAttributeError: 'int' object has no attribute 'a.'\n", "passed": false}
{"task_id": 257, "prediction_id": 36, "generation": "def _attr(obj: object, attr: str) -> object:\n    \"\"\"Nest `getattr` function.\"\"\"\n    return getattr(getattr(obj, attr), attr)\n", "message": "failed: Traceback (most recent call last):\n  File \"/codegendata/human-eval/human_eval/execution.py\", line 57, in unsafe_execute\n    exec(check_program, exec_globals)\n  File \"<string>\", line 626, in <module>\n  File \"<string>\", line 625, in test_0\n  File \"<string>\", line 59, in _attr\nAttributeError: 'int' object has no attribute 'a.'\n", "passed": false}
{"task_id": 257, "prediction_id": 37, "generation": "def _attr(obj: object, attr: str) -> object:\n    \"\"\"Nest `getattr` function.\"\"\"\n    return getattr(getattr(obj, attr), attr)\n", "message": "failed: Traceback (most recent call last):\n  File \"/codegendata/human-eval/human_eval/execution.py\", line 57, in unsafe_execute\n    exec(check_program, exec_globals)\n  File \"<string>\", line 626, in <module>\n  File \"<string>\", line 625, in test_0\n  File \"<string>\", line 59, in _attr\nAttributeError: 'int' object has no attribute 'a.'\n", "passed": false}
{"task_id": 257, "prediction_id": 38, "generation": "def _attr(obj: object, attr: str) -> object:\n    \"\"\"Nest `getattr` function.\"\"\"\n    return getattr(getattr(obj, attr), attr)\n", "message": "failed: Traceback (most recent call last):\n  File \"/codegendata/human-eval/human_eval/execution.py\", line 57, in unsafe_execute\n    exec(check_program, exec_globals)\n  File \"<string>\", line 626, in <module>\n  File \"<string>\", line 625, in test_0\n  File \"<string>\", line 59, in _attr\nAttributeError: 'int' object has no attribute 'a.'\n", "passed": false}
{"task_id": 257, "prediction_id": 39, "generation": "def _attr(obj: object, attr: str) -> object:\n    \"\"\"Nest `getattr` function.\"\"\"\n    return getattr(getattr(obj, attr), attr)\n", "message": "failed: Traceback (most recent call last):\n  File \"/codegendata/human-eval/human_eval/execution.py\", line 57, in unsafe_execute\n    exec(check_program, exec_globals)\n  File \"<string>\", line 626, in <module>\n  File \"<string>\", line 625, in test_0\n  File \"<string>\", line 59, in _attr\nAttributeError: 'int' object has no attribute 'a.'\n", "passed": false}
{"task_id": 257, "prediction_id": 40, "generation": "def _attr(obj: object, attr: str) -> object:\n    \"\"\"Nest `getattr` function.\"\"\"\n    return getattr(getattr(obj, attr), attr)\n", "message": "failed: Traceback (most recent call last):\n  File \"/codegendata/human-eval/human_eval/execution.py\", line 57, in unsafe_execute\n    exec(check_program, exec_globals)\n  File \"<string>\", line 626, in <module>\n  File \"<string>\", line 625, in test_0\n  File \"<string>\", line 59, in _attr\nAttributeError: 'int' object has no attribute 'a.'\n", "passed": false}
{"task_id": 257, "prediction_id": 41, "generation": "def _attr(obj: object, attr: str) -> object:\n    \"\"\"Nest `getattr` function.\"\"\"\n    return getattr(getattr(obj, attr), attr)\n", "message": "failed: Traceback (most recent call last):\n  File \"/codegendata/human-eval/human_eval/execution.py\", line 57, in unsafe_execute\n    exec(check_program, exec_globals)\n  File \"<string>\", line 626, in <module>\n  File \"<string>\", line 625, in test_0\n  File \"<string>\", line 59, in _attr\nAttributeError: 'int' object has no attribute 'a.'\n", "passed": false}
{"task_id": 257, "prediction_id": 42, "generation": "def _attr(obj: object, attr: str) -> object:\n    \"\"\"Nest `getattr` function.\"\"\"\n    return getattr(getattr(obj, attr), attr)\n", "message": "failed: Traceback (most recent call last):\n  File \"/codegendata/human-eval/human_eval/execution.py\", line 57, in unsafe_execute\n    exec(check_program, exec_globals)\n  File \"<string>\", line 626, in <module>\n  File \"<string>\", line 625, in test_0\n  File \"<string>\", line 59, in _attr\nAttributeError: 'int' object has no attribute 'a.'\n", "passed": false}
{"task_id": 257, "prediction_id": 43, "generation": "def _attr(obj: object, attr: str) -> object:\n    \"\"\"Nest `getattr` function.\"\"\"\n    return getattr(getattr(obj, attr), attr)\n", "message": "failed: Traceback (most recent call last):\n  File \"/codegendata/human-eval/human_eval/execution.py\", line 57, in unsafe_execute\n    exec(check_program, exec_globals)\n  File \"<string>\", line 626, in <module>\n  File \"<string>\", line 625, in test_0\n  File \"<string>\", line 59, in _attr\nAttributeError: 'int' object has no attribute 'a.'\n", "passed": false}
{"task_id": 257, "prediction_id": 44, "generation": "def _attr(obj: object, attr: str) -> object:\n    \"\"\"Nest `getattr` function.\"\"\"\n    return getattr(getattr(obj, attr), attr)\n", "message": "failed: Traceback (most recent call last):\n  File \"/codegendata/human-eval/human_eval/execution.py\", line 57, in unsafe_execute\n    exec(check_program, exec_globals)\n  File \"<string>\", line 626, in <module>\n  File \"<string>\", line 625, in test_0\n  File \"<string>\", line 59, in _attr\nAttributeError: 'int' object has no attribute 'a.'\n", "passed": false}
{"task_id": 257, "prediction_id": 45, "generation": "def _attr(obj: object, attr: str) -> object:\n    \"\"\"Nest `getattr` function.\"\"\"\n    return getattr(getattr(obj, attr), attr)\n", "message": "failed: Traceback (most recent call last):\n  File \"/codegendata/human-eval/human_eval/execution.py\", line 57, in unsafe_execute\n    exec(check_program, exec_globals)\n  File \"<string>\", line 626, in <module>\n  File \"<string>\", line 625, in test_0\n  File \"<string>\", line 59, in _attr\nAttributeError: 'int' object has no attribute 'a.'\n", "passed": false}
{"task_id": 257, "prediction_id": 46, "generation": "def _attr(obj: object, attr: str) -> object:\n    \"\"\"Nest `getattr` function.\"\"\"\n    return getattr(getattr(obj, attr), attr)\n", "message": "failed: Traceback (most recent call last):\n  File \"/codegendata/human-eval/human_eval/execution.py\", line 57, in unsafe_execute\n    exec(check_program, exec_globals)\n  File \"<string>\", line 626, in <module>\n  File \"<string>\", line 625, in test_0\n  File \"<string>\", line 59, in _attr\nAttributeError: 'int' object has no attribute 'a.'\n", "passed": false}
{"task_id": 257, "prediction_id": 47, "generation": "def _attr(obj: object, attr: str) -> object:\n    \"\"\"Nest `getattr` function.\"\"\"\n    return getattr(getattr(obj, attr), attr)\n", "message": "failed: Traceback (most recent call last):\n  File \"/codegendata/human-eval/human_eval/execution.py\", line 57, in unsafe_execute\n    exec(check_program, exec_globals)\n  File \"<string>\", line 626, in <module>\n  File \"<string>\", line 625, in test_0\n  File \"<string>\", line 59, in _attr\nAttributeError: 'int' object has no attribute 'a.'\n", "passed": false}
{"task_id": 257, "prediction_id": 48, "generation": "def _attr(obj: object, attr: str) -> object:\n    \"\"\"Nest `getattr` function.\"\"\"\n    return getattr(getattr(obj, attr), attr)\n", "message": "failed: Traceback (most recent call last):\n  File \"/codegendata/human-eval/human_eval/execution.py\", line 57, in unsafe_execute\n    exec(check_program, exec_globals)\n  File \"<string>\", line 626, in <module>\n  File \"<string>\", line 625, in test_0\n  File \"<string>\", line 59, in _attr\nAttributeError: 'int' object has no attribute 'a.'\n", "passed": false}
{"task_id": 257, "prediction_id": 49, "generation": "def _attr(obj: object, attr: str) -> object:\n    \"\"\"Nest `getattr` function.\"\"\"\n    return getattr(getattr(obj, attr), attr)\n", "message": "failed: Traceback (most recent call last):\n  File \"/codegendata/human-eval/human_eval/execution.py\", line 57, in unsafe_execute\n    exec(check_program, exec_globals)\n  File \"<string>\", line 626, in <module>\n  File \"<string>\", line 625, in test_0\n  File \"<string>\", line 59, in _attr\nAttributeError: 'int' object has no attribute 'a.'\n", "passed": false}
